2024-10-05 16:18:26,663 ERROR scheduler Exception in Enqueue Events for Site demo1
Traceback (most recent call last):
  File "/home/madhu/my-bench/apps/frappe/frappe/utils/scheduler.py", line 75, in enqueue_events_for_site
    if is_scheduler_inactive():
  File "/home/madhu/my-bench/apps/frappe/frappe/utils/scheduler.py", line 117, in is_scheduler_inactive
    if is_scheduler_disabled(verbose=verbose):
  File "/home/madhu/my-bench/apps/frappe/frappe/utils/scheduler.py", line 130, in is_scheduler_disabled
    frappe.db.get_single_value("System Settings", "enable_scheduler")
  File "/home/madhu/my-bench/apps/frappe/frappe/database/database.py", line 841, in get_single_value
    ).run()
  File "/home/madhu/my-bench/apps/frappe/frappe/query_builder/utils.py", line 87, in execute_query
    result = frappe.db.sql(query, params, *args, **kwargs)  # nosemgrep
  File "/home/madhu/my-bench/apps/frappe/frappe/database/database.py", line 211, in sql
    self.connect()
  File "/home/madhu/my-bench/apps/frappe/frappe/database/database.py", line 117, in connect
    self._conn: "MariadbConnection" | "PostgresConnection" = self.get_connection()
  File "/home/madhu/my-bench/apps/frappe/frappe/database/mariadb/database.py", line 107, in get_connection
    conn = self._get_connection()
  File "/home/madhu/my-bench/apps/frappe/frappe/database/mariadb/database.py", line 113, in _get_connection
    return self.create_connection()
  File "/home/madhu/my-bench/apps/frappe/frappe/database/mariadb/database.py", line 116, in create_connection
    return pymysql.connect(**self.get_connection_settings())
  File "/home/madhu/my-bench/env/lib/python3.10/site-packages/pymysql/connections.py", line 361, in __init__
    self.connect()
  File "/home/madhu/my-bench/env/lib/python3.10/site-packages/pymysql/connections.py", line 669, in connect
    self._request_authentication()
  File "/home/madhu/my-bench/env/lib/python3.10/site-packages/pymysql/connections.py", line 957, in _request_authentication
    auth_packet = self._read_packet()
  File "/home/madhu/my-bench/env/lib/python3.10/site-packages/pymysql/connections.py", line 775, in _read_packet
    packet.raise_for_error()
  File "/home/madhu/my-bench/env/lib/python3.10/site-packages/pymysql/protocol.py", line 219, in raise_for_error
    err.raise_mysql_exception(self._data)
  File "/home/madhu/my-bench/env/lib/python3.10/site-packages/pymysql/err.py", line 150, in raise_mysql_exception
    raise errorclass(errno, errval)
pymysql.err.OperationalError: (1045, "Access denied for user '_d2dbf53779371df0'@'localhost' (using password: YES)")
2024-10-05 16:19:26,913 ERROR scheduler Exception in Enqueue Events for Site demo1
Traceback (most recent call last):
  File "/home/madhu/my-bench/apps/frappe/frappe/utils/scheduler.py", line 75, in enqueue_events_for_site
    if is_scheduler_inactive():
  File "/home/madhu/my-bench/apps/frappe/frappe/utils/scheduler.py", line 117, in is_scheduler_inactive
    if is_scheduler_disabled(verbose=verbose):
  File "/home/madhu/my-bench/apps/frappe/frappe/utils/scheduler.py", line 130, in is_scheduler_disabled
    frappe.db.get_single_value("System Settings", "enable_scheduler")
  File "/home/madhu/my-bench/apps/frappe/frappe/database/database.py", line 841, in get_single_value
    ).run()
  File "/home/madhu/my-bench/apps/frappe/frappe/query_builder/utils.py", line 87, in execute_query
    result = frappe.db.sql(query, params, *args, **kwargs)  # nosemgrep
  File "/home/madhu/my-bench/apps/frappe/frappe/database/database.py", line 211, in sql
    self.connect()
  File "/home/madhu/my-bench/apps/frappe/frappe/database/database.py", line 117, in connect
    self._conn: "MariadbConnection" | "PostgresConnection" = self.get_connection()
  File "/home/madhu/my-bench/apps/frappe/frappe/database/mariadb/database.py", line 107, in get_connection
    conn = self._get_connection()
  File "/home/madhu/my-bench/apps/frappe/frappe/database/mariadb/database.py", line 113, in _get_connection
    return self.create_connection()
  File "/home/madhu/my-bench/apps/frappe/frappe/database/mariadb/database.py", line 116, in create_connection
    return pymysql.connect(**self.get_connection_settings())
  File "/home/madhu/my-bench/env/lib/python3.10/site-packages/pymysql/connections.py", line 361, in __init__
    self.connect()
  File "/home/madhu/my-bench/env/lib/python3.10/site-packages/pymysql/connections.py", line 669, in connect
    self._request_authentication()
  File "/home/madhu/my-bench/env/lib/python3.10/site-packages/pymysql/connections.py", line 957, in _request_authentication
    auth_packet = self._read_packet()
  File "/home/madhu/my-bench/env/lib/python3.10/site-packages/pymysql/connections.py", line 775, in _read_packet
    packet.raise_for_error()
  File "/home/madhu/my-bench/env/lib/python3.10/site-packages/pymysql/protocol.py", line 219, in raise_for_error
    err.raise_mysql_exception(self._data)
  File "/home/madhu/my-bench/env/lib/python3.10/site-packages/pymysql/err.py", line 150, in raise_mysql_exception
    raise errorclass(errno, errval)
pymysql.err.OperationalError: (1045, "Access denied for user '_d2dbf53779371df0'@'localhost' (using password: YES)")
2024-10-05 16:20:27,238 ERROR scheduler Exception in Enqueue Events for Site demo1
Traceback (most recent call last):
  File "/home/madhu/my-bench/apps/frappe/frappe/utils/scheduler.py", line 75, in enqueue_events_for_site
    if is_scheduler_inactive():
  File "/home/madhu/my-bench/apps/frappe/frappe/utils/scheduler.py", line 117, in is_scheduler_inactive
    if is_scheduler_disabled(verbose=verbose):
  File "/home/madhu/my-bench/apps/frappe/frappe/utils/scheduler.py", line 130, in is_scheduler_disabled
    frappe.db.get_single_value("System Settings", "enable_scheduler")
  File "/home/madhu/my-bench/apps/frappe/frappe/database/database.py", line 841, in get_single_value
    ).run()
  File "/home/madhu/my-bench/apps/frappe/frappe/query_builder/utils.py", line 87, in execute_query
    result = frappe.db.sql(query, params, *args, **kwargs)  # nosemgrep
  File "/home/madhu/my-bench/apps/frappe/frappe/database/database.py", line 211, in sql
    self.connect()
  File "/home/madhu/my-bench/apps/frappe/frappe/database/database.py", line 117, in connect
    self._conn: "MariadbConnection" | "PostgresConnection" = self.get_connection()
  File "/home/madhu/my-bench/apps/frappe/frappe/database/mariadb/database.py", line 107, in get_connection
    conn = self._get_connection()
  File "/home/madhu/my-bench/apps/frappe/frappe/database/mariadb/database.py", line 113, in _get_connection
    return self.create_connection()
  File "/home/madhu/my-bench/apps/frappe/frappe/database/mariadb/database.py", line 116, in create_connection
    return pymysql.connect(**self.get_connection_settings())
  File "/home/madhu/my-bench/env/lib/python3.10/site-packages/pymysql/connections.py", line 361, in __init__
    self.connect()
  File "/home/madhu/my-bench/env/lib/python3.10/site-packages/pymysql/connections.py", line 669, in connect
    self._request_authentication()
  File "/home/madhu/my-bench/env/lib/python3.10/site-packages/pymysql/connections.py", line 957, in _request_authentication
    auth_packet = self._read_packet()
  File "/home/madhu/my-bench/env/lib/python3.10/site-packages/pymysql/connections.py", line 775, in _read_packet
    packet.raise_for_error()
  File "/home/madhu/my-bench/env/lib/python3.10/site-packages/pymysql/protocol.py", line 219, in raise_for_error
    err.raise_mysql_exception(self._data)
  File "/home/madhu/my-bench/env/lib/python3.10/site-packages/pymysql/err.py", line 150, in raise_mysql_exception
    raise errorclass(errno, errval)
pymysql.err.OperationalError: (1045, "Access denied for user '_d2dbf53779371df0'@'localhost' (using password: YES)")
2024-10-05 16:21:27,954 ERROR scheduler Exception in Enqueue Events for Site demo1
Traceback (most recent call last):
  File "/home/madhu/my-bench/apps/frappe/frappe/utils/scheduler.py", line 75, in enqueue_events_for_site
    if is_scheduler_inactive():
  File "/home/madhu/my-bench/apps/frappe/frappe/utils/scheduler.py", line 117, in is_scheduler_inactive
    if is_scheduler_disabled(verbose=verbose):
  File "/home/madhu/my-bench/apps/frappe/frappe/utils/scheduler.py", line 130, in is_scheduler_disabled
    frappe.db.get_single_value("System Settings", "enable_scheduler")
  File "/home/madhu/my-bench/apps/frappe/frappe/database/database.py", line 841, in get_single_value
    ).run()
  File "/home/madhu/my-bench/apps/frappe/frappe/query_builder/utils.py", line 87, in execute_query
    result = frappe.db.sql(query, params, *args, **kwargs)  # nosemgrep
  File "/home/madhu/my-bench/apps/frappe/frappe/database/database.py", line 211, in sql
    self.connect()
  File "/home/madhu/my-bench/apps/frappe/frappe/database/database.py", line 117, in connect
    self._conn: "MariadbConnection" | "PostgresConnection" = self.get_connection()
  File "/home/madhu/my-bench/apps/frappe/frappe/database/mariadb/database.py", line 107, in get_connection
    conn = self._get_connection()
  File "/home/madhu/my-bench/apps/frappe/frappe/database/mariadb/database.py", line 113, in _get_connection
    return self.create_connection()
  File "/home/madhu/my-bench/apps/frappe/frappe/database/mariadb/database.py", line 116, in create_connection
    return pymysql.connect(**self.get_connection_settings())
  File "/home/madhu/my-bench/env/lib/python3.10/site-packages/pymysql/connections.py", line 361, in __init__
    self.connect()
  File "/home/madhu/my-bench/env/lib/python3.10/site-packages/pymysql/connections.py", line 669, in connect
    self._request_authentication()
  File "/home/madhu/my-bench/env/lib/python3.10/site-packages/pymysql/connections.py", line 957, in _request_authentication
    auth_packet = self._read_packet()
  File "/home/madhu/my-bench/env/lib/python3.10/site-packages/pymysql/connections.py", line 775, in _read_packet
    packet.raise_for_error()
  File "/home/madhu/my-bench/env/lib/python3.10/site-packages/pymysql/protocol.py", line 219, in raise_for_error
    err.raise_mysql_exception(self._data)
  File "/home/madhu/my-bench/env/lib/python3.10/site-packages/pymysql/err.py", line 150, in raise_mysql_exception
    raise errorclass(errno, errval)
pymysql.err.OperationalError: (1045, "Access denied for user '_d2dbf53779371df0'@'localhost' (using password: YES)")
2024-10-05 16:22:28,446 ERROR scheduler Exception in Enqueue Events for Site demo1
Traceback (most recent call last):
  File "/home/madhu/my-bench/apps/frappe/frappe/utils/scheduler.py", line 75, in enqueue_events_for_site
    if is_scheduler_inactive():
  File "/home/madhu/my-bench/apps/frappe/frappe/utils/scheduler.py", line 117, in is_scheduler_inactive
    if is_scheduler_disabled(verbose=verbose):
  File "/home/madhu/my-bench/apps/frappe/frappe/utils/scheduler.py", line 130, in is_scheduler_disabled
    frappe.db.get_single_value("System Settings", "enable_scheduler")
  File "/home/madhu/my-bench/apps/frappe/frappe/database/database.py", line 841, in get_single_value
    ).run()
  File "/home/madhu/my-bench/apps/frappe/frappe/query_builder/utils.py", line 87, in execute_query
    result = frappe.db.sql(query, params, *args, **kwargs)  # nosemgrep
  File "/home/madhu/my-bench/apps/frappe/frappe/database/database.py", line 211, in sql
    self.connect()
  File "/home/madhu/my-bench/apps/frappe/frappe/database/database.py", line 117, in connect
    self._conn: "MariadbConnection" | "PostgresConnection" = self.get_connection()
  File "/home/madhu/my-bench/apps/frappe/frappe/database/mariadb/database.py", line 107, in get_connection
    conn = self._get_connection()
  File "/home/madhu/my-bench/apps/frappe/frappe/database/mariadb/database.py", line 113, in _get_connection
    return self.create_connection()
  File "/home/madhu/my-bench/apps/frappe/frappe/database/mariadb/database.py", line 116, in create_connection
    return pymysql.connect(**self.get_connection_settings())
  File "/home/madhu/my-bench/env/lib/python3.10/site-packages/pymysql/connections.py", line 361, in __init__
    self.connect()
  File "/home/madhu/my-bench/env/lib/python3.10/site-packages/pymysql/connections.py", line 669, in connect
    self._request_authentication()
  File "/home/madhu/my-bench/env/lib/python3.10/site-packages/pymysql/connections.py", line 957, in _request_authentication
    auth_packet = self._read_packet()
  File "/home/madhu/my-bench/env/lib/python3.10/site-packages/pymysql/connections.py", line 775, in _read_packet
    packet.raise_for_error()
  File "/home/madhu/my-bench/env/lib/python3.10/site-packages/pymysql/protocol.py", line 219, in raise_for_error
    err.raise_mysql_exception(self._data)
  File "/home/madhu/my-bench/env/lib/python3.10/site-packages/pymysql/err.py", line 150, in raise_mysql_exception
    raise errorclass(errno, errval)
pymysql.err.OperationalError: (1045, "Access denied for user '_d2dbf53779371df0'@'localhost' (using password: YES)")
2024-10-05 16:23:28,742 ERROR scheduler Exception in Enqueue Events for Site demo1
Traceback (most recent call last):
  File "/home/madhu/my-bench/apps/frappe/frappe/utils/scheduler.py", line 75, in enqueue_events_for_site
    if is_scheduler_inactive():
  File "/home/madhu/my-bench/apps/frappe/frappe/utils/scheduler.py", line 117, in is_scheduler_inactive
    if is_scheduler_disabled(verbose=verbose):
  File "/home/madhu/my-bench/apps/frappe/frappe/utils/scheduler.py", line 130, in is_scheduler_disabled
    frappe.db.get_single_value("System Settings", "enable_scheduler")
  File "/home/madhu/my-bench/apps/frappe/frappe/database/database.py", line 841, in get_single_value
    ).run()
  File "/home/madhu/my-bench/apps/frappe/frappe/query_builder/utils.py", line 87, in execute_query
    result = frappe.db.sql(query, params, *args, **kwargs)  # nosemgrep
  File "/home/madhu/my-bench/apps/frappe/frappe/database/database.py", line 211, in sql
    self.connect()
  File "/home/madhu/my-bench/apps/frappe/frappe/database/database.py", line 117, in connect
    self._conn: "MariadbConnection" | "PostgresConnection" = self.get_connection()
  File "/home/madhu/my-bench/apps/frappe/frappe/database/mariadb/database.py", line 107, in get_connection
    conn = self._get_connection()
  File "/home/madhu/my-bench/apps/frappe/frappe/database/mariadb/database.py", line 113, in _get_connection
    return self.create_connection()
  File "/home/madhu/my-bench/apps/frappe/frappe/database/mariadb/database.py", line 116, in create_connection
    return pymysql.connect(**self.get_connection_settings())
  File "/home/madhu/my-bench/env/lib/python3.10/site-packages/pymysql/connections.py", line 361, in __init__
    self.connect()
  File "/home/madhu/my-bench/env/lib/python3.10/site-packages/pymysql/connections.py", line 669, in connect
    self._request_authentication()
  File "/home/madhu/my-bench/env/lib/python3.10/site-packages/pymysql/connections.py", line 957, in _request_authentication
    auth_packet = self._read_packet()
  File "/home/madhu/my-bench/env/lib/python3.10/site-packages/pymysql/connections.py", line 775, in _read_packet
    packet.raise_for_error()
  File "/home/madhu/my-bench/env/lib/python3.10/site-packages/pymysql/protocol.py", line 219, in raise_for_error
    err.raise_mysql_exception(self._data)
  File "/home/madhu/my-bench/env/lib/python3.10/site-packages/pymysql/err.py", line 150, in raise_mysql_exception
    raise errorclass(errno, errval)
pymysql.err.OperationalError: (1045, "Access denied for user '_d2dbf53779371df0'@'localhost' (using password: YES)")
2024-10-05 16:24:29,234 ERROR scheduler Exception in Enqueue Events for Site demo1
Traceback (most recent call last):
  File "/home/madhu/my-bench/apps/frappe/frappe/utils/scheduler.py", line 75, in enqueue_events_for_site
    if is_scheduler_inactive():
  File "/home/madhu/my-bench/apps/frappe/frappe/utils/scheduler.py", line 117, in is_scheduler_inactive
    if is_scheduler_disabled(verbose=verbose):
  File "/home/madhu/my-bench/apps/frappe/frappe/utils/scheduler.py", line 130, in is_scheduler_disabled
    frappe.db.get_single_value("System Settings", "enable_scheduler")
  File "/home/madhu/my-bench/apps/frappe/frappe/database/database.py", line 841, in get_single_value
    ).run()
  File "/home/madhu/my-bench/apps/frappe/frappe/query_builder/utils.py", line 87, in execute_query
    result = frappe.db.sql(query, params, *args, **kwargs)  # nosemgrep
  File "/home/madhu/my-bench/apps/frappe/frappe/database/database.py", line 211, in sql
    self.connect()
  File "/home/madhu/my-bench/apps/frappe/frappe/database/database.py", line 117, in connect
    self._conn: "MariadbConnection" | "PostgresConnection" = self.get_connection()
  File "/home/madhu/my-bench/apps/frappe/frappe/database/mariadb/database.py", line 107, in get_connection
    conn = self._get_connection()
  File "/home/madhu/my-bench/apps/frappe/frappe/database/mariadb/database.py", line 113, in _get_connection
    return self.create_connection()
  File "/home/madhu/my-bench/apps/frappe/frappe/database/mariadb/database.py", line 116, in create_connection
    return pymysql.connect(**self.get_connection_settings())
  File "/home/madhu/my-bench/env/lib/python3.10/site-packages/pymysql/connections.py", line 361, in __init__
    self.connect()
  File "/home/madhu/my-bench/env/lib/python3.10/site-packages/pymysql/connections.py", line 669, in connect
    self._request_authentication()
  File "/home/madhu/my-bench/env/lib/python3.10/site-packages/pymysql/connections.py", line 957, in _request_authentication
    auth_packet = self._read_packet()
  File "/home/madhu/my-bench/env/lib/python3.10/site-packages/pymysql/connections.py", line 775, in _read_packet
    packet.raise_for_error()
  File "/home/madhu/my-bench/env/lib/python3.10/site-packages/pymysql/protocol.py", line 219, in raise_for_error
    err.raise_mysql_exception(self._data)
  File "/home/madhu/my-bench/env/lib/python3.10/site-packages/pymysql/err.py", line 150, in raise_mysql_exception
    raise errorclass(errno, errval)
pymysql.err.OperationalError: (1045, "Access denied for user '_d2dbf53779371df0'@'localhost' (using password: YES)")
2024-10-05 16:25:29,629 ERROR scheduler Exception in Enqueue Events for Site demo1
Traceback (most recent call last):
  File "/home/madhu/my-bench/apps/frappe/frappe/utils/scheduler.py", line 75, in enqueue_events_for_site
    if is_scheduler_inactive():
  File "/home/madhu/my-bench/apps/frappe/frappe/utils/scheduler.py", line 117, in is_scheduler_inactive
    if is_scheduler_disabled(verbose=verbose):
  File "/home/madhu/my-bench/apps/frappe/frappe/utils/scheduler.py", line 130, in is_scheduler_disabled
    frappe.db.get_single_value("System Settings", "enable_scheduler")
  File "/home/madhu/my-bench/apps/frappe/frappe/database/database.py", line 841, in get_single_value
    ).run()
  File "/home/madhu/my-bench/apps/frappe/frappe/query_builder/utils.py", line 87, in execute_query
    result = frappe.db.sql(query, params, *args, **kwargs)  # nosemgrep
  File "/home/madhu/my-bench/apps/frappe/frappe/database/database.py", line 211, in sql
    self.connect()
  File "/home/madhu/my-bench/apps/frappe/frappe/database/database.py", line 117, in connect
    self._conn: "MariadbConnection" | "PostgresConnection" = self.get_connection()
  File "/home/madhu/my-bench/apps/frappe/frappe/database/mariadb/database.py", line 107, in get_connection
    conn = self._get_connection()
  File "/home/madhu/my-bench/apps/frappe/frappe/database/mariadb/database.py", line 113, in _get_connection
    return self.create_connection()
  File "/home/madhu/my-bench/apps/frappe/frappe/database/mariadb/database.py", line 116, in create_connection
    return pymysql.connect(**self.get_connection_settings())
  File "/home/madhu/my-bench/env/lib/python3.10/site-packages/pymysql/connections.py", line 361, in __init__
    self.connect()
  File "/home/madhu/my-bench/env/lib/python3.10/site-packages/pymysql/connections.py", line 669, in connect
    self._request_authentication()
  File "/home/madhu/my-bench/env/lib/python3.10/site-packages/pymysql/connections.py", line 957, in _request_authentication
    auth_packet = self._read_packet()
  File "/home/madhu/my-bench/env/lib/python3.10/site-packages/pymysql/connections.py", line 775, in _read_packet
    packet.raise_for_error()
  File "/home/madhu/my-bench/env/lib/python3.10/site-packages/pymysql/protocol.py", line 219, in raise_for_error
    err.raise_mysql_exception(self._data)
  File "/home/madhu/my-bench/env/lib/python3.10/site-packages/pymysql/err.py", line 150, in raise_mysql_exception
    raise errorclass(errno, errval)
pymysql.err.OperationalError: (1045, "Access denied for user '_d2dbf53779371df0'@'localhost' (using password: YES)")
2024-10-05 16:26:30,422 ERROR scheduler Exception in Enqueue Events for Site demo1
Traceback (most recent call last):
  File "/home/madhu/my-bench/apps/frappe/frappe/utils/scheduler.py", line 75, in enqueue_events_for_site
    if is_scheduler_inactive():
  File "/home/madhu/my-bench/apps/frappe/frappe/utils/scheduler.py", line 117, in is_scheduler_inactive
    if is_scheduler_disabled(verbose=verbose):
  File "/home/madhu/my-bench/apps/frappe/frappe/utils/scheduler.py", line 130, in is_scheduler_disabled
    frappe.db.get_single_value("System Settings", "enable_scheduler")
  File "/home/madhu/my-bench/apps/frappe/frappe/database/database.py", line 841, in get_single_value
    ).run()
  File "/home/madhu/my-bench/apps/frappe/frappe/query_builder/utils.py", line 87, in execute_query
    result = frappe.db.sql(query, params, *args, **kwargs)  # nosemgrep
  File "/home/madhu/my-bench/apps/frappe/frappe/database/database.py", line 211, in sql
    self.connect()
  File "/home/madhu/my-bench/apps/frappe/frappe/database/database.py", line 117, in connect
    self._conn: "MariadbConnection" | "PostgresConnection" = self.get_connection()
  File "/home/madhu/my-bench/apps/frappe/frappe/database/mariadb/database.py", line 107, in get_connection
    conn = self._get_connection()
  File "/home/madhu/my-bench/apps/frappe/frappe/database/mariadb/database.py", line 113, in _get_connection
    return self.create_connection()
  File "/home/madhu/my-bench/apps/frappe/frappe/database/mariadb/database.py", line 116, in create_connection
    return pymysql.connect(**self.get_connection_settings())
  File "/home/madhu/my-bench/env/lib/python3.10/site-packages/pymysql/connections.py", line 361, in __init__
    self.connect()
  File "/home/madhu/my-bench/env/lib/python3.10/site-packages/pymysql/connections.py", line 669, in connect
    self._request_authentication()
  File "/home/madhu/my-bench/env/lib/python3.10/site-packages/pymysql/connections.py", line 957, in _request_authentication
    auth_packet = self._read_packet()
  File "/home/madhu/my-bench/env/lib/python3.10/site-packages/pymysql/connections.py", line 775, in _read_packet
    packet.raise_for_error()
  File "/home/madhu/my-bench/env/lib/python3.10/site-packages/pymysql/protocol.py", line 219, in raise_for_error
    err.raise_mysql_exception(self._data)
  File "/home/madhu/my-bench/env/lib/python3.10/site-packages/pymysql/err.py", line 150, in raise_mysql_exception
    raise errorclass(errno, errval)
pymysql.err.OperationalError: (1045, "Access denied for user '_d2dbf53779371df0'@'localhost' (using password: YES)")
2024-10-05 16:27:30,764 ERROR scheduler Exception in Enqueue Events for Site demo1
Traceback (most recent call last):
  File "/home/madhu/my-bench/apps/frappe/frappe/utils/scheduler.py", line 75, in enqueue_events_for_site
    if is_scheduler_inactive():
  File "/home/madhu/my-bench/apps/frappe/frappe/utils/scheduler.py", line 117, in is_scheduler_inactive
    if is_scheduler_disabled(verbose=verbose):
  File "/home/madhu/my-bench/apps/frappe/frappe/utils/scheduler.py", line 130, in is_scheduler_disabled
    frappe.db.get_single_value("System Settings", "enable_scheduler")
  File "/home/madhu/my-bench/apps/frappe/frappe/database/database.py", line 841, in get_single_value
    ).run()
  File "/home/madhu/my-bench/apps/frappe/frappe/query_builder/utils.py", line 87, in execute_query
    result = frappe.db.sql(query, params, *args, **kwargs)  # nosemgrep
  File "/home/madhu/my-bench/apps/frappe/frappe/database/database.py", line 211, in sql
    self.connect()
  File "/home/madhu/my-bench/apps/frappe/frappe/database/database.py", line 117, in connect
    self._conn: "MariadbConnection" | "PostgresConnection" = self.get_connection()
  File "/home/madhu/my-bench/apps/frappe/frappe/database/mariadb/database.py", line 107, in get_connection
    conn = self._get_connection()
  File "/home/madhu/my-bench/apps/frappe/frappe/database/mariadb/database.py", line 113, in _get_connection
    return self.create_connection()
  File "/home/madhu/my-bench/apps/frappe/frappe/database/mariadb/database.py", line 116, in create_connection
    return pymysql.connect(**self.get_connection_settings())
  File "/home/madhu/my-bench/env/lib/python3.10/site-packages/pymysql/connections.py", line 361, in __init__
    self.connect()
  File "/home/madhu/my-bench/env/lib/python3.10/site-packages/pymysql/connections.py", line 669, in connect
    self._request_authentication()
  File "/home/madhu/my-bench/env/lib/python3.10/site-packages/pymysql/connections.py", line 957, in _request_authentication
    auth_packet = self._read_packet()
  File "/home/madhu/my-bench/env/lib/python3.10/site-packages/pymysql/connections.py", line 775, in _read_packet
    packet.raise_for_error()
  File "/home/madhu/my-bench/env/lib/python3.10/site-packages/pymysql/protocol.py", line 219, in raise_for_error
    err.raise_mysql_exception(self._data)
  File "/home/madhu/my-bench/env/lib/python3.10/site-packages/pymysql/err.py", line 150, in raise_mysql_exception
    raise errorclass(errno, errval)
pymysql.err.OperationalError: (1045, "Access denied for user '_d2dbf53779371df0'@'localhost' (using password: YES)")
2024-10-05 16:28:31,300 ERROR scheduler Exception in Enqueue Events for Site demo1
Traceback (most recent call last):
  File "/home/madhu/my-bench/apps/frappe/frappe/utils/scheduler.py", line 75, in enqueue_events_for_site
    if is_scheduler_inactive():
  File "/home/madhu/my-bench/apps/frappe/frappe/utils/scheduler.py", line 117, in is_scheduler_inactive
    if is_scheduler_disabled(verbose=verbose):
  File "/home/madhu/my-bench/apps/frappe/frappe/utils/scheduler.py", line 130, in is_scheduler_disabled
    frappe.db.get_single_value("System Settings", "enable_scheduler")
  File "/home/madhu/my-bench/apps/frappe/frappe/database/database.py", line 841, in get_single_value
    ).run()
  File "/home/madhu/my-bench/apps/frappe/frappe/query_builder/utils.py", line 87, in execute_query
    result = frappe.db.sql(query, params, *args, **kwargs)  # nosemgrep
  File "/home/madhu/my-bench/apps/frappe/frappe/database/database.py", line 211, in sql
    self.connect()
  File "/home/madhu/my-bench/apps/frappe/frappe/database/database.py", line 117, in connect
    self._conn: "MariadbConnection" | "PostgresConnection" = self.get_connection()
  File "/home/madhu/my-bench/apps/frappe/frappe/database/mariadb/database.py", line 107, in get_connection
    conn = self._get_connection()
  File "/home/madhu/my-bench/apps/frappe/frappe/database/mariadb/database.py", line 113, in _get_connection
    return self.create_connection()
  File "/home/madhu/my-bench/apps/frappe/frappe/database/mariadb/database.py", line 116, in create_connection
    return pymysql.connect(**self.get_connection_settings())
  File "/home/madhu/my-bench/env/lib/python3.10/site-packages/pymysql/connections.py", line 361, in __init__
    self.connect()
  File "/home/madhu/my-bench/env/lib/python3.10/site-packages/pymysql/connections.py", line 669, in connect
    self._request_authentication()
  File "/home/madhu/my-bench/env/lib/python3.10/site-packages/pymysql/connections.py", line 957, in _request_authentication
    auth_packet = self._read_packet()
  File "/home/madhu/my-bench/env/lib/python3.10/site-packages/pymysql/connections.py", line 775, in _read_packet
    packet.raise_for_error()
  File "/home/madhu/my-bench/env/lib/python3.10/site-packages/pymysql/protocol.py", line 219, in raise_for_error
    err.raise_mysql_exception(self._data)
  File "/home/madhu/my-bench/env/lib/python3.10/site-packages/pymysql/err.py", line 150, in raise_mysql_exception
    raise errorclass(errno, errval)
pymysql.err.OperationalError: (1045, "Access denied for user '_d2dbf53779371df0'@'localhost' (using password: YES)")
2024-10-05 16:29:31,645 ERROR scheduler Exception in Enqueue Events for Site demo1
Traceback (most recent call last):
  File "/home/madhu/my-bench/apps/frappe/frappe/utils/scheduler.py", line 75, in enqueue_events_for_site
    if is_scheduler_inactive():
  File "/home/madhu/my-bench/apps/frappe/frappe/utils/scheduler.py", line 117, in is_scheduler_inactive
    if is_scheduler_disabled(verbose=verbose):
  File "/home/madhu/my-bench/apps/frappe/frappe/utils/scheduler.py", line 130, in is_scheduler_disabled
    frappe.db.get_single_value("System Settings", "enable_scheduler")
  File "/home/madhu/my-bench/apps/frappe/frappe/database/database.py", line 841, in get_single_value
    ).run()
  File "/home/madhu/my-bench/apps/frappe/frappe/query_builder/utils.py", line 87, in execute_query
    result = frappe.db.sql(query, params, *args, **kwargs)  # nosemgrep
  File "/home/madhu/my-bench/apps/frappe/frappe/database/database.py", line 211, in sql
    self.connect()
  File "/home/madhu/my-bench/apps/frappe/frappe/database/database.py", line 117, in connect
    self._conn: "MariadbConnection" | "PostgresConnection" = self.get_connection()
  File "/home/madhu/my-bench/apps/frappe/frappe/database/mariadb/database.py", line 107, in get_connection
    conn = self._get_connection()
  File "/home/madhu/my-bench/apps/frappe/frappe/database/mariadb/database.py", line 113, in _get_connection
    return self.create_connection()
  File "/home/madhu/my-bench/apps/frappe/frappe/database/mariadb/database.py", line 116, in create_connection
    return pymysql.connect(**self.get_connection_settings())
  File "/home/madhu/my-bench/env/lib/python3.10/site-packages/pymysql/connections.py", line 361, in __init__
    self.connect()
  File "/home/madhu/my-bench/env/lib/python3.10/site-packages/pymysql/connections.py", line 669, in connect
    self._request_authentication()
  File "/home/madhu/my-bench/env/lib/python3.10/site-packages/pymysql/connections.py", line 957, in _request_authentication
    auth_packet = self._read_packet()
  File "/home/madhu/my-bench/env/lib/python3.10/site-packages/pymysql/connections.py", line 775, in _read_packet
    packet.raise_for_error()
  File "/home/madhu/my-bench/env/lib/python3.10/site-packages/pymysql/protocol.py", line 219, in raise_for_error
    err.raise_mysql_exception(self._data)
  File "/home/madhu/my-bench/env/lib/python3.10/site-packages/pymysql/err.py", line 150, in raise_mysql_exception
    raise errorclass(errno, errval)
pymysql.err.OperationalError: (1045, "Access denied for user '_d2dbf53779371df0'@'localhost' (using password: YES)")
2024-10-05 16:30:31,965 ERROR scheduler Exception in Enqueue Events for Site demo1
Traceback (most recent call last):
  File "/home/madhu/my-bench/apps/frappe/frappe/utils/scheduler.py", line 75, in enqueue_events_for_site
    if is_scheduler_inactive():
  File "/home/madhu/my-bench/apps/frappe/frappe/utils/scheduler.py", line 117, in is_scheduler_inactive
    if is_scheduler_disabled(verbose=verbose):
  File "/home/madhu/my-bench/apps/frappe/frappe/utils/scheduler.py", line 130, in is_scheduler_disabled
    frappe.db.get_single_value("System Settings", "enable_scheduler")
  File "/home/madhu/my-bench/apps/frappe/frappe/database/database.py", line 841, in get_single_value
    ).run()
  File "/home/madhu/my-bench/apps/frappe/frappe/query_builder/utils.py", line 87, in execute_query
    result = frappe.db.sql(query, params, *args, **kwargs)  # nosemgrep
  File "/home/madhu/my-bench/apps/frappe/frappe/database/database.py", line 211, in sql
    self.connect()
  File "/home/madhu/my-bench/apps/frappe/frappe/database/database.py", line 117, in connect
    self._conn: "MariadbConnection" | "PostgresConnection" = self.get_connection()
  File "/home/madhu/my-bench/apps/frappe/frappe/database/mariadb/database.py", line 107, in get_connection
    conn = self._get_connection()
  File "/home/madhu/my-bench/apps/frappe/frappe/database/mariadb/database.py", line 113, in _get_connection
    return self.create_connection()
  File "/home/madhu/my-bench/apps/frappe/frappe/database/mariadb/database.py", line 116, in create_connection
    return pymysql.connect(**self.get_connection_settings())
  File "/home/madhu/my-bench/env/lib/python3.10/site-packages/pymysql/connections.py", line 361, in __init__
    self.connect()
  File "/home/madhu/my-bench/env/lib/python3.10/site-packages/pymysql/connections.py", line 669, in connect
    self._request_authentication()
  File "/home/madhu/my-bench/env/lib/python3.10/site-packages/pymysql/connections.py", line 957, in _request_authentication
    auth_packet = self._read_packet()
  File "/home/madhu/my-bench/env/lib/python3.10/site-packages/pymysql/connections.py", line 775, in _read_packet
    packet.raise_for_error()
  File "/home/madhu/my-bench/env/lib/python3.10/site-packages/pymysql/protocol.py", line 219, in raise_for_error
    err.raise_mysql_exception(self._data)
  File "/home/madhu/my-bench/env/lib/python3.10/site-packages/pymysql/err.py", line 150, in raise_mysql_exception
    raise errorclass(errno, errval)
pymysql.err.OperationalError: (1045, "Access denied for user '_d2dbf53779371df0'@'localhost' (using password: YES)")
2024-10-05 16:31:32,519 ERROR scheduler Exception in Enqueue Events for Site demo1
Traceback (most recent call last):
  File "/home/madhu/my-bench/apps/frappe/frappe/utils/scheduler.py", line 75, in enqueue_events_for_site
    if is_scheduler_inactive():
  File "/home/madhu/my-bench/apps/frappe/frappe/utils/scheduler.py", line 117, in is_scheduler_inactive
    if is_scheduler_disabled(verbose=verbose):
  File "/home/madhu/my-bench/apps/frappe/frappe/utils/scheduler.py", line 130, in is_scheduler_disabled
    frappe.db.get_single_value("System Settings", "enable_scheduler")
  File "/home/madhu/my-bench/apps/frappe/frappe/database/database.py", line 841, in get_single_value
    ).run()
  File "/home/madhu/my-bench/apps/frappe/frappe/query_builder/utils.py", line 87, in execute_query
    result = frappe.db.sql(query, params, *args, **kwargs)  # nosemgrep
  File "/home/madhu/my-bench/apps/frappe/frappe/database/database.py", line 211, in sql
    self.connect()
  File "/home/madhu/my-bench/apps/frappe/frappe/database/database.py", line 117, in connect
    self._conn: "MariadbConnection" | "PostgresConnection" = self.get_connection()
  File "/home/madhu/my-bench/apps/frappe/frappe/database/mariadb/database.py", line 107, in get_connection
    conn = self._get_connection()
  File "/home/madhu/my-bench/apps/frappe/frappe/database/mariadb/database.py", line 113, in _get_connection
    return self.create_connection()
  File "/home/madhu/my-bench/apps/frappe/frappe/database/mariadb/database.py", line 116, in create_connection
    return pymysql.connect(**self.get_connection_settings())
  File "/home/madhu/my-bench/env/lib/python3.10/site-packages/pymysql/connections.py", line 361, in __init__
    self.connect()
  File "/home/madhu/my-bench/env/lib/python3.10/site-packages/pymysql/connections.py", line 669, in connect
    self._request_authentication()
  File "/home/madhu/my-bench/env/lib/python3.10/site-packages/pymysql/connections.py", line 957, in _request_authentication
    auth_packet = self._read_packet()
  File "/home/madhu/my-bench/env/lib/python3.10/site-packages/pymysql/connections.py", line 775, in _read_packet
    packet.raise_for_error()
  File "/home/madhu/my-bench/env/lib/python3.10/site-packages/pymysql/protocol.py", line 219, in raise_for_error
    err.raise_mysql_exception(self._data)
  File "/home/madhu/my-bench/env/lib/python3.10/site-packages/pymysql/err.py", line 150, in raise_mysql_exception
    raise errorclass(errno, errval)
pymysql.err.OperationalError: (1045, "Access denied for user '_d2dbf53779371df0'@'localhost' (using password: YES)")
2024-10-05 16:32:32,606 ERROR scheduler Exception in Enqueue Events for Site demo1
Traceback (most recent call last):
  File "/home/madhu/my-bench/apps/frappe/frappe/utils/scheduler.py", line 75, in enqueue_events_for_site
    if is_scheduler_inactive():
  File "/home/madhu/my-bench/apps/frappe/frappe/utils/scheduler.py", line 117, in is_scheduler_inactive
    if is_scheduler_disabled(verbose=verbose):
  File "/home/madhu/my-bench/apps/frappe/frappe/utils/scheduler.py", line 130, in is_scheduler_disabled
    frappe.db.get_single_value("System Settings", "enable_scheduler")
  File "/home/madhu/my-bench/apps/frappe/frappe/database/database.py", line 841, in get_single_value
    ).run()
  File "/home/madhu/my-bench/apps/frappe/frappe/query_builder/utils.py", line 87, in execute_query
    result = frappe.db.sql(query, params, *args, **kwargs)  # nosemgrep
  File "/home/madhu/my-bench/apps/frappe/frappe/database/database.py", line 211, in sql
    self.connect()
  File "/home/madhu/my-bench/apps/frappe/frappe/database/database.py", line 117, in connect
    self._conn: "MariadbConnection" | "PostgresConnection" = self.get_connection()
  File "/home/madhu/my-bench/apps/frappe/frappe/database/mariadb/database.py", line 107, in get_connection
    conn = self._get_connection()
  File "/home/madhu/my-bench/apps/frappe/frappe/database/mariadb/database.py", line 113, in _get_connection
    return self.create_connection()
  File "/home/madhu/my-bench/apps/frappe/frappe/database/mariadb/database.py", line 116, in create_connection
    return pymysql.connect(**self.get_connection_settings())
  File "/home/madhu/my-bench/env/lib/python3.10/site-packages/pymysql/connections.py", line 361, in __init__
    self.connect()
  File "/home/madhu/my-bench/env/lib/python3.10/site-packages/pymysql/connections.py", line 669, in connect
    self._request_authentication()
  File "/home/madhu/my-bench/env/lib/python3.10/site-packages/pymysql/connections.py", line 957, in _request_authentication
    auth_packet = self._read_packet()
  File "/home/madhu/my-bench/env/lib/python3.10/site-packages/pymysql/connections.py", line 775, in _read_packet
    packet.raise_for_error()
  File "/home/madhu/my-bench/env/lib/python3.10/site-packages/pymysql/protocol.py", line 219, in raise_for_error
    err.raise_mysql_exception(self._data)
  File "/home/madhu/my-bench/env/lib/python3.10/site-packages/pymysql/err.py", line 150, in raise_mysql_exception
    raise errorclass(errno, errval)
pymysql.err.OperationalError: (1045, "Access denied for user '_d2dbf53779371df0'@'localhost' (using password: YES)")
2024-10-05 16:33:33,206 ERROR scheduler Exception in Enqueue Events for Site demo1
Traceback (most recent call last):
  File "/home/madhu/my-bench/apps/frappe/frappe/utils/scheduler.py", line 75, in enqueue_events_for_site
    if is_scheduler_inactive():
  File "/home/madhu/my-bench/apps/frappe/frappe/utils/scheduler.py", line 117, in is_scheduler_inactive
    if is_scheduler_disabled(verbose=verbose):
  File "/home/madhu/my-bench/apps/frappe/frappe/utils/scheduler.py", line 130, in is_scheduler_disabled
    frappe.db.get_single_value("System Settings", "enable_scheduler")
  File "/home/madhu/my-bench/apps/frappe/frappe/database/database.py", line 841, in get_single_value
    ).run()
  File "/home/madhu/my-bench/apps/frappe/frappe/query_builder/utils.py", line 87, in execute_query
    result = frappe.db.sql(query, params, *args, **kwargs)  # nosemgrep
  File "/home/madhu/my-bench/apps/frappe/frappe/database/database.py", line 211, in sql
    self.connect()
  File "/home/madhu/my-bench/apps/frappe/frappe/database/database.py", line 117, in connect
    self._conn: "MariadbConnection" | "PostgresConnection" = self.get_connection()
  File "/home/madhu/my-bench/apps/frappe/frappe/database/mariadb/database.py", line 107, in get_connection
    conn = self._get_connection()
  File "/home/madhu/my-bench/apps/frappe/frappe/database/mariadb/database.py", line 113, in _get_connection
    return self.create_connection()
  File "/home/madhu/my-bench/apps/frappe/frappe/database/mariadb/database.py", line 116, in create_connection
    return pymysql.connect(**self.get_connection_settings())
  File "/home/madhu/my-bench/env/lib/python3.10/site-packages/pymysql/connections.py", line 361, in __init__
    self.connect()
  File "/home/madhu/my-bench/env/lib/python3.10/site-packages/pymysql/connections.py", line 669, in connect
    self._request_authentication()
  File "/home/madhu/my-bench/env/lib/python3.10/site-packages/pymysql/connections.py", line 957, in _request_authentication
    auth_packet = self._read_packet()
  File "/home/madhu/my-bench/env/lib/python3.10/site-packages/pymysql/connections.py", line 775, in _read_packet
    packet.raise_for_error()
  File "/home/madhu/my-bench/env/lib/python3.10/site-packages/pymysql/protocol.py", line 219, in raise_for_error
    err.raise_mysql_exception(self._data)
  File "/home/madhu/my-bench/env/lib/python3.10/site-packages/pymysql/err.py", line 150, in raise_mysql_exception
    raise errorclass(errno, errval)
pymysql.err.OperationalError: (1045, "Access denied for user '_d2dbf53779371df0'@'localhost' (using password: YES)")
2024-10-05 16:34:33,634 ERROR scheduler Exception in Enqueue Events for Site demo1
Traceback (most recent call last):
  File "/home/madhu/my-bench/apps/frappe/frappe/utils/scheduler.py", line 75, in enqueue_events_for_site
    if is_scheduler_inactive():
  File "/home/madhu/my-bench/apps/frappe/frappe/utils/scheduler.py", line 117, in is_scheduler_inactive
    if is_scheduler_disabled(verbose=verbose):
  File "/home/madhu/my-bench/apps/frappe/frappe/utils/scheduler.py", line 130, in is_scheduler_disabled
    frappe.db.get_single_value("System Settings", "enable_scheduler")
  File "/home/madhu/my-bench/apps/frappe/frappe/database/database.py", line 841, in get_single_value
    ).run()
  File "/home/madhu/my-bench/apps/frappe/frappe/query_builder/utils.py", line 87, in execute_query
    result = frappe.db.sql(query, params, *args, **kwargs)  # nosemgrep
  File "/home/madhu/my-bench/apps/frappe/frappe/database/database.py", line 211, in sql
    self.connect()
  File "/home/madhu/my-bench/apps/frappe/frappe/database/database.py", line 117, in connect
    self._conn: "MariadbConnection" | "PostgresConnection" = self.get_connection()
  File "/home/madhu/my-bench/apps/frappe/frappe/database/mariadb/database.py", line 107, in get_connection
    conn = self._get_connection()
  File "/home/madhu/my-bench/apps/frappe/frappe/database/mariadb/database.py", line 113, in _get_connection
    return self.create_connection()
  File "/home/madhu/my-bench/apps/frappe/frappe/database/mariadb/database.py", line 116, in create_connection
    return pymysql.connect(**self.get_connection_settings())
  File "/home/madhu/my-bench/env/lib/python3.10/site-packages/pymysql/connections.py", line 361, in __init__
    self.connect()
  File "/home/madhu/my-bench/env/lib/python3.10/site-packages/pymysql/connections.py", line 669, in connect
    self._request_authentication()
  File "/home/madhu/my-bench/env/lib/python3.10/site-packages/pymysql/connections.py", line 957, in _request_authentication
    auth_packet = self._read_packet()
  File "/home/madhu/my-bench/env/lib/python3.10/site-packages/pymysql/connections.py", line 775, in _read_packet
    packet.raise_for_error()
  File "/home/madhu/my-bench/env/lib/python3.10/site-packages/pymysql/protocol.py", line 219, in raise_for_error
    err.raise_mysql_exception(self._data)
  File "/home/madhu/my-bench/env/lib/python3.10/site-packages/pymysql/err.py", line 150, in raise_mysql_exception
    raise errorclass(errno, errval)
pymysql.err.OperationalError: (1045, "Access denied for user '_d2dbf53779371df0'@'localhost' (using password: YES)")
2024-10-05 16:35:34,011 ERROR scheduler Exception in Enqueue Events for Site demo1
Traceback (most recent call last):
  File "/home/madhu/my-bench/apps/frappe/frappe/utils/scheduler.py", line 75, in enqueue_events_for_site
    if is_scheduler_inactive():
  File "/home/madhu/my-bench/apps/frappe/frappe/utils/scheduler.py", line 117, in is_scheduler_inactive
    if is_scheduler_disabled(verbose=verbose):
  File "/home/madhu/my-bench/apps/frappe/frappe/utils/scheduler.py", line 130, in is_scheduler_disabled
    frappe.db.get_single_value("System Settings", "enable_scheduler")
  File "/home/madhu/my-bench/apps/frappe/frappe/database/database.py", line 841, in get_single_value
    ).run()
  File "/home/madhu/my-bench/apps/frappe/frappe/query_builder/utils.py", line 87, in execute_query
    result = frappe.db.sql(query, params, *args, **kwargs)  # nosemgrep
  File "/home/madhu/my-bench/apps/frappe/frappe/database/database.py", line 211, in sql
    self.connect()
  File "/home/madhu/my-bench/apps/frappe/frappe/database/database.py", line 117, in connect
    self._conn: "MariadbConnection" | "PostgresConnection" = self.get_connection()
  File "/home/madhu/my-bench/apps/frappe/frappe/database/mariadb/database.py", line 107, in get_connection
    conn = self._get_connection()
  File "/home/madhu/my-bench/apps/frappe/frappe/database/mariadb/database.py", line 113, in _get_connection
    return self.create_connection()
  File "/home/madhu/my-bench/apps/frappe/frappe/database/mariadb/database.py", line 116, in create_connection
    return pymysql.connect(**self.get_connection_settings())
  File "/home/madhu/my-bench/env/lib/python3.10/site-packages/pymysql/connections.py", line 361, in __init__
    self.connect()
  File "/home/madhu/my-bench/env/lib/python3.10/site-packages/pymysql/connections.py", line 669, in connect
    self._request_authentication()
  File "/home/madhu/my-bench/env/lib/python3.10/site-packages/pymysql/connections.py", line 957, in _request_authentication
    auth_packet = self._read_packet()
  File "/home/madhu/my-bench/env/lib/python3.10/site-packages/pymysql/connections.py", line 775, in _read_packet
    packet.raise_for_error()
  File "/home/madhu/my-bench/env/lib/python3.10/site-packages/pymysql/protocol.py", line 219, in raise_for_error
    err.raise_mysql_exception(self._data)
  File "/home/madhu/my-bench/env/lib/python3.10/site-packages/pymysql/err.py", line 150, in raise_mysql_exception
    raise errorclass(errno, errval)
pymysql.err.OperationalError: (1045, "Access denied for user '_d2dbf53779371df0'@'localhost' (using password: YES)")
2024-10-05 16:36:34,548 ERROR scheduler Exception in Enqueue Events for Site demo1
Traceback (most recent call last):
  File "/home/madhu/my-bench/apps/frappe/frappe/utils/scheduler.py", line 75, in enqueue_events_for_site
    if is_scheduler_inactive():
  File "/home/madhu/my-bench/apps/frappe/frappe/utils/scheduler.py", line 117, in is_scheduler_inactive
    if is_scheduler_disabled(verbose=verbose):
  File "/home/madhu/my-bench/apps/frappe/frappe/utils/scheduler.py", line 130, in is_scheduler_disabled
    frappe.db.get_single_value("System Settings", "enable_scheduler")
  File "/home/madhu/my-bench/apps/frappe/frappe/database/database.py", line 841, in get_single_value
    ).run()
  File "/home/madhu/my-bench/apps/frappe/frappe/query_builder/utils.py", line 87, in execute_query
    result = frappe.db.sql(query, params, *args, **kwargs)  # nosemgrep
  File "/home/madhu/my-bench/apps/frappe/frappe/database/database.py", line 211, in sql
    self.connect()
  File "/home/madhu/my-bench/apps/frappe/frappe/database/database.py", line 117, in connect
    self._conn: "MariadbConnection" | "PostgresConnection" = self.get_connection()
  File "/home/madhu/my-bench/apps/frappe/frappe/database/mariadb/database.py", line 107, in get_connection
    conn = self._get_connection()
  File "/home/madhu/my-bench/apps/frappe/frappe/database/mariadb/database.py", line 113, in _get_connection
    return self.create_connection()
  File "/home/madhu/my-bench/apps/frappe/frappe/database/mariadb/database.py", line 116, in create_connection
    return pymysql.connect(**self.get_connection_settings())
  File "/home/madhu/my-bench/env/lib/python3.10/site-packages/pymysql/connections.py", line 361, in __init__
    self.connect()
  File "/home/madhu/my-bench/env/lib/python3.10/site-packages/pymysql/connections.py", line 669, in connect
    self._request_authentication()
  File "/home/madhu/my-bench/env/lib/python3.10/site-packages/pymysql/connections.py", line 957, in _request_authentication
    auth_packet = self._read_packet()
  File "/home/madhu/my-bench/env/lib/python3.10/site-packages/pymysql/connections.py", line 775, in _read_packet
    packet.raise_for_error()
  File "/home/madhu/my-bench/env/lib/python3.10/site-packages/pymysql/protocol.py", line 219, in raise_for_error
    err.raise_mysql_exception(self._data)
  File "/home/madhu/my-bench/env/lib/python3.10/site-packages/pymysql/err.py", line 150, in raise_mysql_exception
    raise errorclass(errno, errval)
pymysql.err.OperationalError: (1045, "Access denied for user '_d2dbf53779371df0'@'localhost' (using password: YES)")
2024-10-05 16:37:34,944 ERROR scheduler Exception in Enqueue Events for Site demo1
Traceback (most recent call last):
  File "/home/madhu/my-bench/apps/frappe/frappe/utils/scheduler.py", line 75, in enqueue_events_for_site
    if is_scheduler_inactive():
  File "/home/madhu/my-bench/apps/frappe/frappe/utils/scheduler.py", line 117, in is_scheduler_inactive
    if is_scheduler_disabled(verbose=verbose):
  File "/home/madhu/my-bench/apps/frappe/frappe/utils/scheduler.py", line 130, in is_scheduler_disabled
    frappe.db.get_single_value("System Settings", "enable_scheduler")
  File "/home/madhu/my-bench/apps/frappe/frappe/database/database.py", line 841, in get_single_value
    ).run()
  File "/home/madhu/my-bench/apps/frappe/frappe/query_builder/utils.py", line 87, in execute_query
    result = frappe.db.sql(query, params, *args, **kwargs)  # nosemgrep
  File "/home/madhu/my-bench/apps/frappe/frappe/database/database.py", line 211, in sql
    self.connect()
  File "/home/madhu/my-bench/apps/frappe/frappe/database/database.py", line 117, in connect
    self._conn: "MariadbConnection" | "PostgresConnection" = self.get_connection()
  File "/home/madhu/my-bench/apps/frappe/frappe/database/mariadb/database.py", line 107, in get_connection
    conn = self._get_connection()
  File "/home/madhu/my-bench/apps/frappe/frappe/database/mariadb/database.py", line 113, in _get_connection
    return self.create_connection()
  File "/home/madhu/my-bench/apps/frappe/frappe/database/mariadb/database.py", line 116, in create_connection
    return pymysql.connect(**self.get_connection_settings())
  File "/home/madhu/my-bench/env/lib/python3.10/site-packages/pymysql/connections.py", line 361, in __init__
    self.connect()
  File "/home/madhu/my-bench/env/lib/python3.10/site-packages/pymysql/connections.py", line 669, in connect
    self._request_authentication()
  File "/home/madhu/my-bench/env/lib/python3.10/site-packages/pymysql/connections.py", line 957, in _request_authentication
    auth_packet = self._read_packet()
  File "/home/madhu/my-bench/env/lib/python3.10/site-packages/pymysql/connections.py", line 775, in _read_packet
    packet.raise_for_error()
  File "/home/madhu/my-bench/env/lib/python3.10/site-packages/pymysql/protocol.py", line 219, in raise_for_error
    err.raise_mysql_exception(self._data)
  File "/home/madhu/my-bench/env/lib/python3.10/site-packages/pymysql/err.py", line 150, in raise_mysql_exception
    raise errorclass(errno, errval)
pymysql.err.OperationalError: (1045, "Access denied for user '_d2dbf53779371df0'@'localhost' (using password: YES)")
2024-10-05 16:38:35,276 ERROR scheduler Exception in Enqueue Events for Site demo1
Traceback (most recent call last):
  File "/home/madhu/my-bench/apps/frappe/frappe/utils/scheduler.py", line 75, in enqueue_events_for_site
    if is_scheduler_inactive():
  File "/home/madhu/my-bench/apps/frappe/frappe/utils/scheduler.py", line 117, in is_scheduler_inactive
    if is_scheduler_disabled(verbose=verbose):
  File "/home/madhu/my-bench/apps/frappe/frappe/utils/scheduler.py", line 130, in is_scheduler_disabled
    frappe.db.get_single_value("System Settings", "enable_scheduler")
  File "/home/madhu/my-bench/apps/frappe/frappe/database/database.py", line 841, in get_single_value
    ).run()
  File "/home/madhu/my-bench/apps/frappe/frappe/query_builder/utils.py", line 87, in execute_query
    result = frappe.db.sql(query, params, *args, **kwargs)  # nosemgrep
  File "/home/madhu/my-bench/apps/frappe/frappe/database/database.py", line 211, in sql
    self.connect()
  File "/home/madhu/my-bench/apps/frappe/frappe/database/database.py", line 117, in connect
    self._conn: "MariadbConnection" | "PostgresConnection" = self.get_connection()
  File "/home/madhu/my-bench/apps/frappe/frappe/database/mariadb/database.py", line 107, in get_connection
    conn = self._get_connection()
  File "/home/madhu/my-bench/apps/frappe/frappe/database/mariadb/database.py", line 113, in _get_connection
    return self.create_connection()
  File "/home/madhu/my-bench/apps/frappe/frappe/database/mariadb/database.py", line 116, in create_connection
    return pymysql.connect(**self.get_connection_settings())
  File "/home/madhu/my-bench/env/lib/python3.10/site-packages/pymysql/connections.py", line 361, in __init__
    self.connect()
  File "/home/madhu/my-bench/env/lib/python3.10/site-packages/pymysql/connections.py", line 669, in connect
    self._request_authentication()
  File "/home/madhu/my-bench/env/lib/python3.10/site-packages/pymysql/connections.py", line 957, in _request_authentication
    auth_packet = self._read_packet()
  File "/home/madhu/my-bench/env/lib/python3.10/site-packages/pymysql/connections.py", line 775, in _read_packet
    packet.raise_for_error()
  File "/home/madhu/my-bench/env/lib/python3.10/site-packages/pymysql/protocol.py", line 219, in raise_for_error
    err.raise_mysql_exception(self._data)
  File "/home/madhu/my-bench/env/lib/python3.10/site-packages/pymysql/err.py", line 150, in raise_mysql_exception
    raise errorclass(errno, errval)
pymysql.err.OperationalError: (1045, "Access denied for user '_d2dbf53779371df0'@'localhost' (using password: YES)")
2024-10-05 16:39:35,960 ERROR scheduler Exception in Enqueue Events for Site demo1
Traceback (most recent call last):
  File "/home/madhu/my-bench/apps/frappe/frappe/utils/scheduler.py", line 75, in enqueue_events_for_site
    if is_scheduler_inactive():
  File "/home/madhu/my-bench/apps/frappe/frappe/utils/scheduler.py", line 117, in is_scheduler_inactive
    if is_scheduler_disabled(verbose=verbose):
  File "/home/madhu/my-bench/apps/frappe/frappe/utils/scheduler.py", line 130, in is_scheduler_disabled
    frappe.db.get_single_value("System Settings", "enable_scheduler")
  File "/home/madhu/my-bench/apps/frappe/frappe/database/database.py", line 841, in get_single_value
    ).run()
  File "/home/madhu/my-bench/apps/frappe/frappe/query_builder/utils.py", line 87, in execute_query
    result = frappe.db.sql(query, params, *args, **kwargs)  # nosemgrep
  File "/home/madhu/my-bench/apps/frappe/frappe/database/database.py", line 211, in sql
    self.connect()
  File "/home/madhu/my-bench/apps/frappe/frappe/database/database.py", line 117, in connect
    self._conn: "MariadbConnection" | "PostgresConnection" = self.get_connection()
  File "/home/madhu/my-bench/apps/frappe/frappe/database/mariadb/database.py", line 107, in get_connection
    conn = self._get_connection()
  File "/home/madhu/my-bench/apps/frappe/frappe/database/mariadb/database.py", line 113, in _get_connection
    return self.create_connection()
  File "/home/madhu/my-bench/apps/frappe/frappe/database/mariadb/database.py", line 116, in create_connection
    return pymysql.connect(**self.get_connection_settings())
  File "/home/madhu/my-bench/env/lib/python3.10/site-packages/pymysql/connections.py", line 361, in __init__
    self.connect()
  File "/home/madhu/my-bench/env/lib/python3.10/site-packages/pymysql/connections.py", line 669, in connect
    self._request_authentication()
  File "/home/madhu/my-bench/env/lib/python3.10/site-packages/pymysql/connections.py", line 957, in _request_authentication
    auth_packet = self._read_packet()
  File "/home/madhu/my-bench/env/lib/python3.10/site-packages/pymysql/connections.py", line 775, in _read_packet
    packet.raise_for_error()
  File "/home/madhu/my-bench/env/lib/python3.10/site-packages/pymysql/protocol.py", line 219, in raise_for_error
    err.raise_mysql_exception(self._data)
  File "/home/madhu/my-bench/env/lib/python3.10/site-packages/pymysql/err.py", line 150, in raise_mysql_exception
    raise errorclass(errno, errval)
pymysql.err.OperationalError: (1045, "Access denied for user '_d2dbf53779371df0'@'localhost' (using password: YES)")
