2024-11-06 12:01:53,310 ERROR scheduler Exception in Enqueue Events for Site newsite1
Traceback (most recent call last):
  File "/home/madhu/my-bench/apps/frappe/frappe/utils/scheduler.py", line 75, in enqueue_events_for_site
    if is_scheduler_inactive():
  File "/home/madhu/my-bench/apps/frappe/frappe/utils/scheduler.py", line 117, in is_scheduler_inactive
    if is_scheduler_disabled(verbose=verbose):
  File "/home/madhu/my-bench/apps/frappe/frappe/utils/scheduler.py", line 130, in is_scheduler_disabled
    frappe.db.get_single_value("System Settings", "enable_scheduler")
  File "/home/madhu/my-bench/apps/frappe/frappe/database/database.py", line 841, in get_single_value
    ).run()
  File "/home/madhu/my-bench/apps/frappe/frappe/query_builder/utils.py", line 87, in execute_query
    result = frappe.db.sql(query, params, *args, **kwargs)  # nosemgrep
  File "/home/madhu/my-bench/apps/frappe/frappe/database/database.py", line 211, in sql
    self.connect()
  File "/home/madhu/my-bench/apps/frappe/frappe/database/database.py", line 117, in connect
    self._conn: "MariadbConnection" | "PostgresConnection" = self.get_connection()
  File "/home/madhu/my-bench/apps/frappe/frappe/database/mariadb/database.py", line 107, in get_connection
    conn = self._get_connection()
  File "/home/madhu/my-bench/apps/frappe/frappe/database/mariadb/database.py", line 113, in _get_connection
    return self.create_connection()
  File "/home/madhu/my-bench/apps/frappe/frappe/database/mariadb/database.py", line 116, in create_connection
    return pymysql.connect(**self.get_connection_settings())
  File "/home/madhu/my-bench/env/lib/python3.10/site-packages/pymysql/connections.py", line 361, in __init__
    self.connect()
  File "/home/madhu/my-bench/env/lib/python3.10/site-packages/pymysql/connections.py", line 669, in connect
    self._request_authentication()
  File "/home/madhu/my-bench/env/lib/python3.10/site-packages/pymysql/connections.py", line 957, in _request_authentication
    auth_packet = self._read_packet()
  File "/home/madhu/my-bench/env/lib/python3.10/site-packages/pymysql/connections.py", line 775, in _read_packet
    packet.raise_for_error()
  File "/home/madhu/my-bench/env/lib/python3.10/site-packages/pymysql/protocol.py", line 219, in raise_for_error
    err.raise_mysql_exception(self._data)
  File "/home/madhu/my-bench/env/lib/python3.10/site-packages/pymysql/err.py", line 150, in raise_mysql_exception
    raise errorclass(errno, errval)
pymysql.err.OperationalError: (1045, "Access denied for user '_933473f0cb047aa4'@'localhost' (using password: YES)")
2024-11-06 12:02:53,760 ERROR scheduler Exception in Enqueue Events for Site newsite1
Traceback (most recent call last):
  File "/home/madhu/my-bench/apps/frappe/frappe/utils/scheduler.py", line 75, in enqueue_events_for_site
    if is_scheduler_inactive():
  File "/home/madhu/my-bench/apps/frappe/frappe/utils/scheduler.py", line 117, in is_scheduler_inactive
    if is_scheduler_disabled(verbose=verbose):
  File "/home/madhu/my-bench/apps/frappe/frappe/utils/scheduler.py", line 130, in is_scheduler_disabled
    frappe.db.get_single_value("System Settings", "enable_scheduler")
  File "/home/madhu/my-bench/apps/frappe/frappe/database/database.py", line 841, in get_single_value
    ).run()
  File "/home/madhu/my-bench/apps/frappe/frappe/query_builder/utils.py", line 87, in execute_query
    result = frappe.db.sql(query, params, *args, **kwargs)  # nosemgrep
  File "/home/madhu/my-bench/apps/frappe/frappe/database/database.py", line 211, in sql
    self.connect()
  File "/home/madhu/my-bench/apps/frappe/frappe/database/database.py", line 117, in connect
    self._conn: "MariadbConnection" | "PostgresConnection" = self.get_connection()
  File "/home/madhu/my-bench/apps/frappe/frappe/database/mariadb/database.py", line 107, in get_connection
    conn = self._get_connection()
  File "/home/madhu/my-bench/apps/frappe/frappe/database/mariadb/database.py", line 113, in _get_connection
    return self.create_connection()
  File "/home/madhu/my-bench/apps/frappe/frappe/database/mariadb/database.py", line 116, in create_connection
    return pymysql.connect(**self.get_connection_settings())
  File "/home/madhu/my-bench/env/lib/python3.10/site-packages/pymysql/connections.py", line 361, in __init__
    self.connect()
  File "/home/madhu/my-bench/env/lib/python3.10/site-packages/pymysql/connections.py", line 669, in connect
    self._request_authentication()
  File "/home/madhu/my-bench/env/lib/python3.10/site-packages/pymysql/connections.py", line 957, in _request_authentication
    auth_packet = self._read_packet()
  File "/home/madhu/my-bench/env/lib/python3.10/site-packages/pymysql/connections.py", line 775, in _read_packet
    packet.raise_for_error()
  File "/home/madhu/my-bench/env/lib/python3.10/site-packages/pymysql/protocol.py", line 219, in raise_for_error
    err.raise_mysql_exception(self._data)
  File "/home/madhu/my-bench/env/lib/python3.10/site-packages/pymysql/err.py", line 150, in raise_mysql_exception
    raise errorclass(errno, errval)
pymysql.err.OperationalError: (1045, "Access denied for user '_933473f0cb047aa4'@'localhost' (using password: YES)")
2024-11-06 12:03:53,985 ERROR scheduler Exception in Enqueue Events for Site newsite1
Traceback (most recent call last):
  File "/home/madhu/my-bench/apps/frappe/frappe/utils/scheduler.py", line 75, in enqueue_events_for_site
    if is_scheduler_inactive():
  File "/home/madhu/my-bench/apps/frappe/frappe/utils/scheduler.py", line 117, in is_scheduler_inactive
    if is_scheduler_disabled(verbose=verbose):
  File "/home/madhu/my-bench/apps/frappe/frappe/utils/scheduler.py", line 130, in is_scheduler_disabled
    frappe.db.get_single_value("System Settings", "enable_scheduler")
  File "/home/madhu/my-bench/apps/frappe/frappe/database/database.py", line 841, in get_single_value
    ).run()
  File "/home/madhu/my-bench/apps/frappe/frappe/query_builder/utils.py", line 87, in execute_query
    result = frappe.db.sql(query, params, *args, **kwargs)  # nosemgrep
  File "/home/madhu/my-bench/apps/frappe/frappe/database/database.py", line 211, in sql
    self.connect()
  File "/home/madhu/my-bench/apps/frappe/frappe/database/database.py", line 117, in connect
    self._conn: "MariadbConnection" | "PostgresConnection" = self.get_connection()
  File "/home/madhu/my-bench/apps/frappe/frappe/database/mariadb/database.py", line 107, in get_connection
    conn = self._get_connection()
  File "/home/madhu/my-bench/apps/frappe/frappe/database/mariadb/database.py", line 113, in _get_connection
    return self.create_connection()
  File "/home/madhu/my-bench/apps/frappe/frappe/database/mariadb/database.py", line 116, in create_connection
    return pymysql.connect(**self.get_connection_settings())
  File "/home/madhu/my-bench/env/lib/python3.10/site-packages/pymysql/connections.py", line 361, in __init__
    self.connect()
  File "/home/madhu/my-bench/env/lib/python3.10/site-packages/pymysql/connections.py", line 669, in connect
    self._request_authentication()
  File "/home/madhu/my-bench/env/lib/python3.10/site-packages/pymysql/connections.py", line 957, in _request_authentication
    auth_packet = self._read_packet()
  File "/home/madhu/my-bench/env/lib/python3.10/site-packages/pymysql/connections.py", line 775, in _read_packet
    packet.raise_for_error()
  File "/home/madhu/my-bench/env/lib/python3.10/site-packages/pymysql/protocol.py", line 219, in raise_for_error
    err.raise_mysql_exception(self._data)
  File "/home/madhu/my-bench/env/lib/python3.10/site-packages/pymysql/err.py", line 150, in raise_mysql_exception
    raise errorclass(errno, errval)
pymysql.err.OperationalError: (1045, "Access denied for user '_933473f0cb047aa4'@'localhost' (using password: YES)")
2024-11-06 12:04:54,473 ERROR scheduler Exception in Enqueue Events for Site newsite1
Traceback (most recent call last):
  File "/home/madhu/my-bench/apps/frappe/frappe/utils/scheduler.py", line 75, in enqueue_events_for_site
    if is_scheduler_inactive():
  File "/home/madhu/my-bench/apps/frappe/frappe/utils/scheduler.py", line 117, in is_scheduler_inactive
    if is_scheduler_disabled(verbose=verbose):
  File "/home/madhu/my-bench/apps/frappe/frappe/utils/scheduler.py", line 130, in is_scheduler_disabled
    frappe.db.get_single_value("System Settings", "enable_scheduler")
  File "/home/madhu/my-bench/apps/frappe/frappe/database/database.py", line 841, in get_single_value
    ).run()
  File "/home/madhu/my-bench/apps/frappe/frappe/query_builder/utils.py", line 87, in execute_query
    result = frappe.db.sql(query, params, *args, **kwargs)  # nosemgrep
  File "/home/madhu/my-bench/apps/frappe/frappe/database/database.py", line 211, in sql
    self.connect()
  File "/home/madhu/my-bench/apps/frappe/frappe/database/database.py", line 117, in connect
    self._conn: "MariadbConnection" | "PostgresConnection" = self.get_connection()
  File "/home/madhu/my-bench/apps/frappe/frappe/database/mariadb/database.py", line 107, in get_connection
    conn = self._get_connection()
  File "/home/madhu/my-bench/apps/frappe/frappe/database/mariadb/database.py", line 113, in _get_connection
    return self.create_connection()
  File "/home/madhu/my-bench/apps/frappe/frappe/database/mariadb/database.py", line 116, in create_connection
    return pymysql.connect(**self.get_connection_settings())
  File "/home/madhu/my-bench/env/lib/python3.10/site-packages/pymysql/connections.py", line 361, in __init__
    self.connect()
  File "/home/madhu/my-bench/env/lib/python3.10/site-packages/pymysql/connections.py", line 669, in connect
    self._request_authentication()
  File "/home/madhu/my-bench/env/lib/python3.10/site-packages/pymysql/connections.py", line 957, in _request_authentication
    auth_packet = self._read_packet()
  File "/home/madhu/my-bench/env/lib/python3.10/site-packages/pymysql/connections.py", line 775, in _read_packet
    packet.raise_for_error()
  File "/home/madhu/my-bench/env/lib/python3.10/site-packages/pymysql/protocol.py", line 219, in raise_for_error
    err.raise_mysql_exception(self._data)
  File "/home/madhu/my-bench/env/lib/python3.10/site-packages/pymysql/err.py", line 150, in raise_mysql_exception
    raise errorclass(errno, errval)
pymysql.err.OperationalError: (1045, "Access denied for user '_933473f0cb047aa4'@'localhost' (using password: YES)")
2024-11-06 12:05:54,683 ERROR scheduler Exception in Enqueue Events for Site newsite1
Traceback (most recent call last):
  File "/home/madhu/my-bench/apps/frappe/frappe/utils/scheduler.py", line 75, in enqueue_events_for_site
    if is_scheduler_inactive():
  File "/home/madhu/my-bench/apps/frappe/frappe/utils/scheduler.py", line 117, in is_scheduler_inactive
    if is_scheduler_disabled(verbose=verbose):
  File "/home/madhu/my-bench/apps/frappe/frappe/utils/scheduler.py", line 130, in is_scheduler_disabled
    frappe.db.get_single_value("System Settings", "enable_scheduler")
  File "/home/madhu/my-bench/apps/frappe/frappe/database/database.py", line 841, in get_single_value
    ).run()
  File "/home/madhu/my-bench/apps/frappe/frappe/query_builder/utils.py", line 87, in execute_query
    result = frappe.db.sql(query, params, *args, **kwargs)  # nosemgrep
  File "/home/madhu/my-bench/apps/frappe/frappe/database/database.py", line 211, in sql
    self.connect()
  File "/home/madhu/my-bench/apps/frappe/frappe/database/database.py", line 117, in connect
    self._conn: "MariadbConnection" | "PostgresConnection" = self.get_connection()
  File "/home/madhu/my-bench/apps/frappe/frappe/database/mariadb/database.py", line 107, in get_connection
    conn = self._get_connection()
  File "/home/madhu/my-bench/apps/frappe/frappe/database/mariadb/database.py", line 113, in _get_connection
    return self.create_connection()
  File "/home/madhu/my-bench/apps/frappe/frappe/database/mariadb/database.py", line 116, in create_connection
    return pymysql.connect(**self.get_connection_settings())
  File "/home/madhu/my-bench/env/lib/python3.10/site-packages/pymysql/connections.py", line 361, in __init__
    self.connect()
  File "/home/madhu/my-bench/env/lib/python3.10/site-packages/pymysql/connections.py", line 669, in connect
    self._request_authentication()
  File "/home/madhu/my-bench/env/lib/python3.10/site-packages/pymysql/connections.py", line 957, in _request_authentication
    auth_packet = self._read_packet()
  File "/home/madhu/my-bench/env/lib/python3.10/site-packages/pymysql/connections.py", line 775, in _read_packet
    packet.raise_for_error()
  File "/home/madhu/my-bench/env/lib/python3.10/site-packages/pymysql/protocol.py", line 219, in raise_for_error
    err.raise_mysql_exception(self._data)
  File "/home/madhu/my-bench/env/lib/python3.10/site-packages/pymysql/err.py", line 150, in raise_mysql_exception
    raise errorclass(errno, errval)
pymysql.err.OperationalError: (1045, "Access denied for user '_933473f0cb047aa4'@'localhost' (using password: YES)")
2024-11-06 12:06:55,125 ERROR scheduler Exception in Enqueue Events for Site newsite1
Traceback (most recent call last):
  File "/home/madhu/my-bench/apps/frappe/frappe/utils/scheduler.py", line 75, in enqueue_events_for_site
    if is_scheduler_inactive():
  File "/home/madhu/my-bench/apps/frappe/frappe/utils/scheduler.py", line 117, in is_scheduler_inactive
    if is_scheduler_disabled(verbose=verbose):
  File "/home/madhu/my-bench/apps/frappe/frappe/utils/scheduler.py", line 130, in is_scheduler_disabled
    frappe.db.get_single_value("System Settings", "enable_scheduler")
  File "/home/madhu/my-bench/apps/frappe/frappe/database/database.py", line 841, in get_single_value
    ).run()
  File "/home/madhu/my-bench/apps/frappe/frappe/query_builder/utils.py", line 87, in execute_query
    result = frappe.db.sql(query, params, *args, **kwargs)  # nosemgrep
  File "/home/madhu/my-bench/apps/frappe/frappe/database/database.py", line 211, in sql
    self.connect()
  File "/home/madhu/my-bench/apps/frappe/frappe/database/database.py", line 117, in connect
    self._conn: "MariadbConnection" | "PostgresConnection" = self.get_connection()
  File "/home/madhu/my-bench/apps/frappe/frappe/database/mariadb/database.py", line 107, in get_connection
    conn = self._get_connection()
  File "/home/madhu/my-bench/apps/frappe/frappe/database/mariadb/database.py", line 113, in _get_connection
    return self.create_connection()
  File "/home/madhu/my-bench/apps/frappe/frappe/database/mariadb/database.py", line 116, in create_connection
    return pymysql.connect(**self.get_connection_settings())
  File "/home/madhu/my-bench/env/lib/python3.10/site-packages/pymysql/connections.py", line 361, in __init__
    self.connect()
  File "/home/madhu/my-bench/env/lib/python3.10/site-packages/pymysql/connections.py", line 669, in connect
    self._request_authentication()
  File "/home/madhu/my-bench/env/lib/python3.10/site-packages/pymysql/connections.py", line 957, in _request_authentication
    auth_packet = self._read_packet()
  File "/home/madhu/my-bench/env/lib/python3.10/site-packages/pymysql/connections.py", line 775, in _read_packet
    packet.raise_for_error()
  File "/home/madhu/my-bench/env/lib/python3.10/site-packages/pymysql/protocol.py", line 219, in raise_for_error
    err.raise_mysql_exception(self._data)
  File "/home/madhu/my-bench/env/lib/python3.10/site-packages/pymysql/err.py", line 150, in raise_mysql_exception
    raise errorclass(errno, errval)
pymysql.err.OperationalError: (1045, "Access denied for user '_933473f0cb047aa4'@'localhost' (using password: YES)")
2024-11-06 12:07:55,559 ERROR scheduler Exception in Enqueue Events for Site newsite1
Traceback (most recent call last):
  File "/home/madhu/my-bench/apps/frappe/frappe/utils/scheduler.py", line 75, in enqueue_events_for_site
    if is_scheduler_inactive():
  File "/home/madhu/my-bench/apps/frappe/frappe/utils/scheduler.py", line 117, in is_scheduler_inactive
    if is_scheduler_disabled(verbose=verbose):
  File "/home/madhu/my-bench/apps/frappe/frappe/utils/scheduler.py", line 130, in is_scheduler_disabled
    frappe.db.get_single_value("System Settings", "enable_scheduler")
  File "/home/madhu/my-bench/apps/frappe/frappe/database/database.py", line 841, in get_single_value
    ).run()
  File "/home/madhu/my-bench/apps/frappe/frappe/query_builder/utils.py", line 87, in execute_query
    result = frappe.db.sql(query, params, *args, **kwargs)  # nosemgrep
  File "/home/madhu/my-bench/apps/frappe/frappe/database/database.py", line 211, in sql
    self.connect()
  File "/home/madhu/my-bench/apps/frappe/frappe/database/database.py", line 117, in connect
    self._conn: "MariadbConnection" | "PostgresConnection" = self.get_connection()
  File "/home/madhu/my-bench/apps/frappe/frappe/database/mariadb/database.py", line 107, in get_connection
    conn = self._get_connection()
  File "/home/madhu/my-bench/apps/frappe/frappe/database/mariadb/database.py", line 113, in _get_connection
    return self.create_connection()
  File "/home/madhu/my-bench/apps/frappe/frappe/database/mariadb/database.py", line 116, in create_connection
    return pymysql.connect(**self.get_connection_settings())
  File "/home/madhu/my-bench/env/lib/python3.10/site-packages/pymysql/connections.py", line 361, in __init__
    self.connect()
  File "/home/madhu/my-bench/env/lib/python3.10/site-packages/pymysql/connections.py", line 669, in connect
    self._request_authentication()
  File "/home/madhu/my-bench/env/lib/python3.10/site-packages/pymysql/connections.py", line 957, in _request_authentication
    auth_packet = self._read_packet()
  File "/home/madhu/my-bench/env/lib/python3.10/site-packages/pymysql/connections.py", line 775, in _read_packet
    packet.raise_for_error()
  File "/home/madhu/my-bench/env/lib/python3.10/site-packages/pymysql/protocol.py", line 219, in raise_for_error
    err.raise_mysql_exception(self._data)
  File "/home/madhu/my-bench/env/lib/python3.10/site-packages/pymysql/err.py", line 150, in raise_mysql_exception
    raise errorclass(errno, errval)
pymysql.err.OperationalError: (1045, "Access denied for user '_933473f0cb047aa4'@'localhost' (using password: YES)")
2024-11-06 12:08:56,031 ERROR scheduler Exception in Enqueue Events for Site newsite1
Traceback (most recent call last):
  File "/home/madhu/my-bench/apps/frappe/frappe/utils/scheduler.py", line 75, in enqueue_events_for_site
    if is_scheduler_inactive():
  File "/home/madhu/my-bench/apps/frappe/frappe/utils/scheduler.py", line 117, in is_scheduler_inactive
    if is_scheduler_disabled(verbose=verbose):
  File "/home/madhu/my-bench/apps/frappe/frappe/utils/scheduler.py", line 130, in is_scheduler_disabled
    frappe.db.get_single_value("System Settings", "enable_scheduler")
  File "/home/madhu/my-bench/apps/frappe/frappe/database/database.py", line 841, in get_single_value
    ).run()
  File "/home/madhu/my-bench/apps/frappe/frappe/query_builder/utils.py", line 87, in execute_query
    result = frappe.db.sql(query, params, *args, **kwargs)  # nosemgrep
  File "/home/madhu/my-bench/apps/frappe/frappe/database/database.py", line 211, in sql
    self.connect()
  File "/home/madhu/my-bench/apps/frappe/frappe/database/database.py", line 117, in connect
    self._conn: "MariadbConnection" | "PostgresConnection" = self.get_connection()
  File "/home/madhu/my-bench/apps/frappe/frappe/database/mariadb/database.py", line 107, in get_connection
    conn = self._get_connection()
  File "/home/madhu/my-bench/apps/frappe/frappe/database/mariadb/database.py", line 113, in _get_connection
    return self.create_connection()
  File "/home/madhu/my-bench/apps/frappe/frappe/database/mariadb/database.py", line 116, in create_connection
    return pymysql.connect(**self.get_connection_settings())
  File "/home/madhu/my-bench/env/lib/python3.10/site-packages/pymysql/connections.py", line 361, in __init__
    self.connect()
  File "/home/madhu/my-bench/env/lib/python3.10/site-packages/pymysql/connections.py", line 669, in connect
    self._request_authentication()
  File "/home/madhu/my-bench/env/lib/python3.10/site-packages/pymysql/connections.py", line 957, in _request_authentication
    auth_packet = self._read_packet()
  File "/home/madhu/my-bench/env/lib/python3.10/site-packages/pymysql/connections.py", line 775, in _read_packet
    packet.raise_for_error()
  File "/home/madhu/my-bench/env/lib/python3.10/site-packages/pymysql/protocol.py", line 219, in raise_for_error
    err.raise_mysql_exception(self._data)
  File "/home/madhu/my-bench/env/lib/python3.10/site-packages/pymysql/err.py", line 150, in raise_mysql_exception
    raise errorclass(errno, errval)
pymysql.err.OperationalError: (1045, "Access denied for user '_933473f0cb047aa4'@'localhost' (using password: YES)")
2024-11-06 12:09:56,397 ERROR scheduler Exception in Enqueue Events for Site newsite1
Traceback (most recent call last):
  File "/home/madhu/my-bench/apps/frappe/frappe/utils/scheduler.py", line 75, in enqueue_events_for_site
    if is_scheduler_inactive():
  File "/home/madhu/my-bench/apps/frappe/frappe/utils/scheduler.py", line 117, in is_scheduler_inactive
    if is_scheduler_disabled(verbose=verbose):
  File "/home/madhu/my-bench/apps/frappe/frappe/utils/scheduler.py", line 130, in is_scheduler_disabled
    frappe.db.get_single_value("System Settings", "enable_scheduler")
  File "/home/madhu/my-bench/apps/frappe/frappe/database/database.py", line 841, in get_single_value
    ).run()
  File "/home/madhu/my-bench/apps/frappe/frappe/query_builder/utils.py", line 87, in execute_query
    result = frappe.db.sql(query, params, *args, **kwargs)  # nosemgrep
  File "/home/madhu/my-bench/apps/frappe/frappe/database/database.py", line 211, in sql
    self.connect()
  File "/home/madhu/my-bench/apps/frappe/frappe/database/database.py", line 117, in connect
    self._conn: "MariadbConnection" | "PostgresConnection" = self.get_connection()
  File "/home/madhu/my-bench/apps/frappe/frappe/database/mariadb/database.py", line 107, in get_connection
    conn = self._get_connection()
  File "/home/madhu/my-bench/apps/frappe/frappe/database/mariadb/database.py", line 113, in _get_connection
    return self.create_connection()
  File "/home/madhu/my-bench/apps/frappe/frappe/database/mariadb/database.py", line 116, in create_connection
    return pymysql.connect(**self.get_connection_settings())
  File "/home/madhu/my-bench/env/lib/python3.10/site-packages/pymysql/connections.py", line 361, in __init__
    self.connect()
  File "/home/madhu/my-bench/env/lib/python3.10/site-packages/pymysql/connections.py", line 669, in connect
    self._request_authentication()
  File "/home/madhu/my-bench/env/lib/python3.10/site-packages/pymysql/connections.py", line 957, in _request_authentication
    auth_packet = self._read_packet()
  File "/home/madhu/my-bench/env/lib/python3.10/site-packages/pymysql/connections.py", line 775, in _read_packet
    packet.raise_for_error()
  File "/home/madhu/my-bench/env/lib/python3.10/site-packages/pymysql/protocol.py", line 219, in raise_for_error
    err.raise_mysql_exception(self._data)
  File "/home/madhu/my-bench/env/lib/python3.10/site-packages/pymysql/err.py", line 150, in raise_mysql_exception
    raise errorclass(errno, errval)
pymysql.err.OperationalError: (1045, "Access denied for user '_933473f0cb047aa4'@'localhost' (using password: YES)")
2024-11-06 12:10:56,832 ERROR scheduler Exception in Enqueue Events for Site newsite1
Traceback (most recent call last):
  File "/home/madhu/my-bench/apps/frappe/frappe/utils/scheduler.py", line 75, in enqueue_events_for_site
    if is_scheduler_inactive():
  File "/home/madhu/my-bench/apps/frappe/frappe/utils/scheduler.py", line 117, in is_scheduler_inactive
    if is_scheduler_disabled(verbose=verbose):
  File "/home/madhu/my-bench/apps/frappe/frappe/utils/scheduler.py", line 130, in is_scheduler_disabled
    frappe.db.get_single_value("System Settings", "enable_scheduler")
  File "/home/madhu/my-bench/apps/frappe/frappe/database/database.py", line 841, in get_single_value
    ).run()
  File "/home/madhu/my-bench/apps/frappe/frappe/query_builder/utils.py", line 87, in execute_query
    result = frappe.db.sql(query, params, *args, **kwargs)  # nosemgrep
  File "/home/madhu/my-bench/apps/frappe/frappe/database/database.py", line 211, in sql
    self.connect()
  File "/home/madhu/my-bench/apps/frappe/frappe/database/database.py", line 117, in connect
    self._conn: "MariadbConnection" | "PostgresConnection" = self.get_connection()
  File "/home/madhu/my-bench/apps/frappe/frappe/database/mariadb/database.py", line 107, in get_connection
    conn = self._get_connection()
  File "/home/madhu/my-bench/apps/frappe/frappe/database/mariadb/database.py", line 113, in _get_connection
    return self.create_connection()
  File "/home/madhu/my-bench/apps/frappe/frappe/database/mariadb/database.py", line 116, in create_connection
    return pymysql.connect(**self.get_connection_settings())
  File "/home/madhu/my-bench/env/lib/python3.10/site-packages/pymysql/connections.py", line 361, in __init__
    self.connect()
  File "/home/madhu/my-bench/env/lib/python3.10/site-packages/pymysql/connections.py", line 669, in connect
    self._request_authentication()
  File "/home/madhu/my-bench/env/lib/python3.10/site-packages/pymysql/connections.py", line 957, in _request_authentication
    auth_packet = self._read_packet()
  File "/home/madhu/my-bench/env/lib/python3.10/site-packages/pymysql/connections.py", line 775, in _read_packet
    packet.raise_for_error()
  File "/home/madhu/my-bench/env/lib/python3.10/site-packages/pymysql/protocol.py", line 219, in raise_for_error
    err.raise_mysql_exception(self._data)
  File "/home/madhu/my-bench/env/lib/python3.10/site-packages/pymysql/err.py", line 150, in raise_mysql_exception
    raise errorclass(errno, errval)
pymysql.err.OperationalError: (1045, "Access denied for user '_933473f0cb047aa4'@'localhost' (using password: YES)")
2024-11-06 12:11:57,159 ERROR scheduler Exception in Enqueue Events for Site newsite1
Traceback (most recent call last):
  File "/home/madhu/my-bench/apps/frappe/frappe/utils/scheduler.py", line 75, in enqueue_events_for_site
    if is_scheduler_inactive():
  File "/home/madhu/my-bench/apps/frappe/frappe/utils/scheduler.py", line 117, in is_scheduler_inactive
    if is_scheduler_disabled(verbose=verbose):
  File "/home/madhu/my-bench/apps/frappe/frappe/utils/scheduler.py", line 130, in is_scheduler_disabled
    frappe.db.get_single_value("System Settings", "enable_scheduler")
  File "/home/madhu/my-bench/apps/frappe/frappe/database/database.py", line 841, in get_single_value
    ).run()
  File "/home/madhu/my-bench/apps/frappe/frappe/query_builder/utils.py", line 87, in execute_query
    result = frappe.db.sql(query, params, *args, **kwargs)  # nosemgrep
  File "/home/madhu/my-bench/apps/frappe/frappe/database/database.py", line 211, in sql
    self.connect()
  File "/home/madhu/my-bench/apps/frappe/frappe/database/database.py", line 117, in connect
    self._conn: "MariadbConnection" | "PostgresConnection" = self.get_connection()
  File "/home/madhu/my-bench/apps/frappe/frappe/database/mariadb/database.py", line 107, in get_connection
    conn = self._get_connection()
  File "/home/madhu/my-bench/apps/frappe/frappe/database/mariadb/database.py", line 113, in _get_connection
    return self.create_connection()
  File "/home/madhu/my-bench/apps/frappe/frappe/database/mariadb/database.py", line 116, in create_connection
    return pymysql.connect(**self.get_connection_settings())
  File "/home/madhu/my-bench/env/lib/python3.10/site-packages/pymysql/connections.py", line 361, in __init__
    self.connect()
  File "/home/madhu/my-bench/env/lib/python3.10/site-packages/pymysql/connections.py", line 669, in connect
    self._request_authentication()
  File "/home/madhu/my-bench/env/lib/python3.10/site-packages/pymysql/connections.py", line 957, in _request_authentication
    auth_packet = self._read_packet()
  File "/home/madhu/my-bench/env/lib/python3.10/site-packages/pymysql/connections.py", line 775, in _read_packet
    packet.raise_for_error()
  File "/home/madhu/my-bench/env/lib/python3.10/site-packages/pymysql/protocol.py", line 219, in raise_for_error
    err.raise_mysql_exception(self._data)
  File "/home/madhu/my-bench/env/lib/python3.10/site-packages/pymysql/err.py", line 150, in raise_mysql_exception
    raise errorclass(errno, errval)
pymysql.err.OperationalError: (1045, "Access denied for user '_933473f0cb047aa4'@'localhost' (using password: YES)")
2024-11-06 12:12:57,296 ERROR scheduler Exception in Enqueue Events for Site newsite1
Traceback (most recent call last):
  File "/home/madhu/my-bench/apps/frappe/frappe/utils/scheduler.py", line 75, in enqueue_events_for_site
    if is_scheduler_inactive():
  File "/home/madhu/my-bench/apps/frappe/frappe/utils/scheduler.py", line 117, in is_scheduler_inactive
    if is_scheduler_disabled(verbose=verbose):
  File "/home/madhu/my-bench/apps/frappe/frappe/utils/scheduler.py", line 130, in is_scheduler_disabled
    frappe.db.get_single_value("System Settings", "enable_scheduler")
  File "/home/madhu/my-bench/apps/frappe/frappe/database/database.py", line 841, in get_single_value
    ).run()
  File "/home/madhu/my-bench/apps/frappe/frappe/query_builder/utils.py", line 87, in execute_query
    result = frappe.db.sql(query, params, *args, **kwargs)  # nosemgrep
  File "/home/madhu/my-bench/apps/frappe/frappe/database/database.py", line 211, in sql
    self.connect()
  File "/home/madhu/my-bench/apps/frappe/frappe/database/database.py", line 117, in connect
    self._conn: "MariadbConnection" | "PostgresConnection" = self.get_connection()
  File "/home/madhu/my-bench/apps/frappe/frappe/database/mariadb/database.py", line 107, in get_connection
    conn = self._get_connection()
  File "/home/madhu/my-bench/apps/frappe/frappe/database/mariadb/database.py", line 113, in _get_connection
    return self.create_connection()
  File "/home/madhu/my-bench/apps/frappe/frappe/database/mariadb/database.py", line 116, in create_connection
    return pymysql.connect(**self.get_connection_settings())
  File "/home/madhu/my-bench/env/lib/python3.10/site-packages/pymysql/connections.py", line 361, in __init__
    self.connect()
  File "/home/madhu/my-bench/env/lib/python3.10/site-packages/pymysql/connections.py", line 669, in connect
    self._request_authentication()
  File "/home/madhu/my-bench/env/lib/python3.10/site-packages/pymysql/connections.py", line 957, in _request_authentication
    auth_packet = self._read_packet()
  File "/home/madhu/my-bench/env/lib/python3.10/site-packages/pymysql/connections.py", line 775, in _read_packet
    packet.raise_for_error()
  File "/home/madhu/my-bench/env/lib/python3.10/site-packages/pymysql/protocol.py", line 219, in raise_for_error
    err.raise_mysql_exception(self._data)
  File "/home/madhu/my-bench/env/lib/python3.10/site-packages/pymysql/err.py", line 150, in raise_mysql_exception
    raise errorclass(errno, errval)
pymysql.err.OperationalError: (1045, "Access denied for user '_933473f0cb047aa4'@'localhost' (using password: YES)")
2024-11-06 12:13:57,675 ERROR scheduler Exception in Enqueue Events for Site newsite1
Traceback (most recent call last):
  File "/home/madhu/my-bench/apps/frappe/frappe/utils/scheduler.py", line 75, in enqueue_events_for_site
    if is_scheduler_inactive():
  File "/home/madhu/my-bench/apps/frappe/frappe/utils/scheduler.py", line 117, in is_scheduler_inactive
    if is_scheduler_disabled(verbose=verbose):
  File "/home/madhu/my-bench/apps/frappe/frappe/utils/scheduler.py", line 130, in is_scheduler_disabled
    frappe.db.get_single_value("System Settings", "enable_scheduler")
  File "/home/madhu/my-bench/apps/frappe/frappe/database/database.py", line 841, in get_single_value
    ).run()
  File "/home/madhu/my-bench/apps/frappe/frappe/query_builder/utils.py", line 87, in execute_query
    result = frappe.db.sql(query, params, *args, **kwargs)  # nosemgrep
  File "/home/madhu/my-bench/apps/frappe/frappe/database/database.py", line 211, in sql
    self.connect()
  File "/home/madhu/my-bench/apps/frappe/frappe/database/database.py", line 117, in connect
    self._conn: "MariadbConnection" | "PostgresConnection" = self.get_connection()
  File "/home/madhu/my-bench/apps/frappe/frappe/database/mariadb/database.py", line 107, in get_connection
    conn = self._get_connection()
  File "/home/madhu/my-bench/apps/frappe/frappe/database/mariadb/database.py", line 113, in _get_connection
    return self.create_connection()
  File "/home/madhu/my-bench/apps/frappe/frappe/database/mariadb/database.py", line 116, in create_connection
    return pymysql.connect(**self.get_connection_settings())
  File "/home/madhu/my-bench/env/lib/python3.10/site-packages/pymysql/connections.py", line 361, in __init__
    self.connect()
  File "/home/madhu/my-bench/env/lib/python3.10/site-packages/pymysql/connections.py", line 669, in connect
    self._request_authentication()
  File "/home/madhu/my-bench/env/lib/python3.10/site-packages/pymysql/connections.py", line 957, in _request_authentication
    auth_packet = self._read_packet()
  File "/home/madhu/my-bench/env/lib/python3.10/site-packages/pymysql/connections.py", line 775, in _read_packet
    packet.raise_for_error()
  File "/home/madhu/my-bench/env/lib/python3.10/site-packages/pymysql/protocol.py", line 219, in raise_for_error
    err.raise_mysql_exception(self._data)
  File "/home/madhu/my-bench/env/lib/python3.10/site-packages/pymysql/err.py", line 150, in raise_mysql_exception
    raise errorclass(errno, errval)
pymysql.err.OperationalError: (1045, "Access denied for user '_933473f0cb047aa4'@'localhost' (using password: YES)")
2024-11-06 12:14:58,017 ERROR scheduler Exception in Enqueue Events for Site newsite1
Traceback (most recent call last):
  File "/home/madhu/my-bench/apps/frappe/frappe/utils/scheduler.py", line 75, in enqueue_events_for_site
    if is_scheduler_inactive():
  File "/home/madhu/my-bench/apps/frappe/frappe/utils/scheduler.py", line 117, in is_scheduler_inactive
    if is_scheduler_disabled(verbose=verbose):
  File "/home/madhu/my-bench/apps/frappe/frappe/utils/scheduler.py", line 130, in is_scheduler_disabled
    frappe.db.get_single_value("System Settings", "enable_scheduler")
  File "/home/madhu/my-bench/apps/frappe/frappe/database/database.py", line 841, in get_single_value
    ).run()
  File "/home/madhu/my-bench/apps/frappe/frappe/query_builder/utils.py", line 87, in execute_query
    result = frappe.db.sql(query, params, *args, **kwargs)  # nosemgrep
  File "/home/madhu/my-bench/apps/frappe/frappe/database/database.py", line 211, in sql
    self.connect()
  File "/home/madhu/my-bench/apps/frappe/frappe/database/database.py", line 117, in connect
    self._conn: "MariadbConnection" | "PostgresConnection" = self.get_connection()
  File "/home/madhu/my-bench/apps/frappe/frappe/database/mariadb/database.py", line 107, in get_connection
    conn = self._get_connection()
  File "/home/madhu/my-bench/apps/frappe/frappe/database/mariadb/database.py", line 113, in _get_connection
    return self.create_connection()
  File "/home/madhu/my-bench/apps/frappe/frappe/database/mariadb/database.py", line 116, in create_connection
    return pymysql.connect(**self.get_connection_settings())
  File "/home/madhu/my-bench/env/lib/python3.10/site-packages/pymysql/connections.py", line 361, in __init__
    self.connect()
  File "/home/madhu/my-bench/env/lib/python3.10/site-packages/pymysql/connections.py", line 669, in connect
    self._request_authentication()
  File "/home/madhu/my-bench/env/lib/python3.10/site-packages/pymysql/connections.py", line 957, in _request_authentication
    auth_packet = self._read_packet()
  File "/home/madhu/my-bench/env/lib/python3.10/site-packages/pymysql/connections.py", line 775, in _read_packet
    packet.raise_for_error()
  File "/home/madhu/my-bench/env/lib/python3.10/site-packages/pymysql/protocol.py", line 219, in raise_for_error
    err.raise_mysql_exception(self._data)
  File "/home/madhu/my-bench/env/lib/python3.10/site-packages/pymysql/err.py", line 150, in raise_mysql_exception
    raise errorclass(errno, errval)
pymysql.err.OperationalError: (1045, "Access denied for user '_933473f0cb047aa4'@'localhost' (using password: YES)")
2024-11-06 12:15:58,694 ERROR scheduler Exception in Enqueue Events for Site newsite1
Traceback (most recent call last):
  File "/home/madhu/my-bench/apps/frappe/frappe/utils/scheduler.py", line 75, in enqueue_events_for_site
    if is_scheduler_inactive():
  File "/home/madhu/my-bench/apps/frappe/frappe/utils/scheduler.py", line 117, in is_scheduler_inactive
    if is_scheduler_disabled(verbose=verbose):
  File "/home/madhu/my-bench/apps/frappe/frappe/utils/scheduler.py", line 130, in is_scheduler_disabled
    frappe.db.get_single_value("System Settings", "enable_scheduler")
  File "/home/madhu/my-bench/apps/frappe/frappe/database/database.py", line 841, in get_single_value
    ).run()
  File "/home/madhu/my-bench/apps/frappe/frappe/query_builder/utils.py", line 87, in execute_query
    result = frappe.db.sql(query, params, *args, **kwargs)  # nosemgrep
  File "/home/madhu/my-bench/apps/frappe/frappe/database/database.py", line 211, in sql
    self.connect()
  File "/home/madhu/my-bench/apps/frappe/frappe/database/database.py", line 117, in connect
    self._conn: "MariadbConnection" | "PostgresConnection" = self.get_connection()
  File "/home/madhu/my-bench/apps/frappe/frappe/database/mariadb/database.py", line 107, in get_connection
    conn = self._get_connection()
  File "/home/madhu/my-bench/apps/frappe/frappe/database/mariadb/database.py", line 113, in _get_connection
    return self.create_connection()
  File "/home/madhu/my-bench/apps/frappe/frappe/database/mariadb/database.py", line 116, in create_connection
    return pymysql.connect(**self.get_connection_settings())
  File "/home/madhu/my-bench/env/lib/python3.10/site-packages/pymysql/connections.py", line 361, in __init__
    self.connect()
  File "/home/madhu/my-bench/env/lib/python3.10/site-packages/pymysql/connections.py", line 669, in connect
    self._request_authentication()
  File "/home/madhu/my-bench/env/lib/python3.10/site-packages/pymysql/connections.py", line 957, in _request_authentication
    auth_packet = self._read_packet()
  File "/home/madhu/my-bench/env/lib/python3.10/site-packages/pymysql/connections.py", line 775, in _read_packet
    packet.raise_for_error()
  File "/home/madhu/my-bench/env/lib/python3.10/site-packages/pymysql/protocol.py", line 219, in raise_for_error
    err.raise_mysql_exception(self._data)
  File "/home/madhu/my-bench/env/lib/python3.10/site-packages/pymysql/err.py", line 150, in raise_mysql_exception
    raise errorclass(errno, errval)
pymysql.err.OperationalError: (1045, "Access denied for user '_933473f0cb047aa4'@'localhost' (using password: YES)")
2024-11-06 15:56:45,451 ERROR scheduler Exception in Enqueue Events for Site newsite1
Traceback (most recent call last):
  File "/home/madhu/my-bench/apps/frappe/frappe/utils/scheduler.py", line 75, in enqueue_events_for_site
    if is_scheduler_inactive():
  File "/home/madhu/my-bench/apps/frappe/frappe/utils/scheduler.py", line 117, in is_scheduler_inactive
    if is_scheduler_disabled(verbose=verbose):
  File "/home/madhu/my-bench/apps/frappe/frappe/utils/scheduler.py", line 130, in is_scheduler_disabled
    frappe.db.get_single_value("System Settings", "enable_scheduler")
  File "/home/madhu/my-bench/apps/frappe/frappe/database/database.py", line 841, in get_single_value
    ).run()
  File "/home/madhu/my-bench/apps/frappe/frappe/query_builder/utils.py", line 87, in execute_query
    result = frappe.db.sql(query, params, *args, **kwargs)  # nosemgrep
  File "/home/madhu/my-bench/apps/frappe/frappe/database/database.py", line 211, in sql
    self.connect()
  File "/home/madhu/my-bench/apps/frappe/frappe/database/database.py", line 117, in connect
    self._conn: "MariadbConnection" | "PostgresConnection" = self.get_connection()
  File "/home/madhu/my-bench/apps/frappe/frappe/database/mariadb/database.py", line 107, in get_connection
    conn = self._get_connection()
  File "/home/madhu/my-bench/apps/frappe/frappe/database/mariadb/database.py", line 113, in _get_connection
    return self.create_connection()
  File "/home/madhu/my-bench/apps/frappe/frappe/database/mariadb/database.py", line 116, in create_connection
    return pymysql.connect(**self.get_connection_settings())
  File "/home/madhu/my-bench/env/lib/python3.10/site-packages/pymysql/connections.py", line 361, in __init__
    self.connect()
  File "/home/madhu/my-bench/env/lib/python3.10/site-packages/pymysql/connections.py", line 669, in connect
    self._request_authentication()
  File "/home/madhu/my-bench/env/lib/python3.10/site-packages/pymysql/connections.py", line 957, in _request_authentication
    auth_packet = self._read_packet()
  File "/home/madhu/my-bench/env/lib/python3.10/site-packages/pymysql/connections.py", line 775, in _read_packet
    packet.raise_for_error()
  File "/home/madhu/my-bench/env/lib/python3.10/site-packages/pymysql/protocol.py", line 219, in raise_for_error
    err.raise_mysql_exception(self._data)
  File "/home/madhu/my-bench/env/lib/python3.10/site-packages/pymysql/err.py", line 150, in raise_mysql_exception
    raise errorclass(errno, errval)
pymysql.err.OperationalError: (1045, "Access denied for user '_933473f0cb047aa4'@'localhost' (using password: YES)")
2024-11-06 15:57:46,107 ERROR scheduler Exception in Enqueue Events for Site newsite1
Traceback (most recent call last):
  File "/home/madhu/my-bench/apps/frappe/frappe/utils/scheduler.py", line 75, in enqueue_events_for_site
    if is_scheduler_inactive():
  File "/home/madhu/my-bench/apps/frappe/frappe/utils/scheduler.py", line 117, in is_scheduler_inactive
    if is_scheduler_disabled(verbose=verbose):
  File "/home/madhu/my-bench/apps/frappe/frappe/utils/scheduler.py", line 130, in is_scheduler_disabled
    frappe.db.get_single_value("System Settings", "enable_scheduler")
  File "/home/madhu/my-bench/apps/frappe/frappe/database/database.py", line 841, in get_single_value
    ).run()
  File "/home/madhu/my-bench/apps/frappe/frappe/query_builder/utils.py", line 87, in execute_query
    result = frappe.db.sql(query, params, *args, **kwargs)  # nosemgrep
  File "/home/madhu/my-bench/apps/frappe/frappe/database/database.py", line 211, in sql
    self.connect()
  File "/home/madhu/my-bench/apps/frappe/frappe/database/database.py", line 117, in connect
    self._conn: "MariadbConnection" | "PostgresConnection" = self.get_connection()
  File "/home/madhu/my-bench/apps/frappe/frappe/database/mariadb/database.py", line 107, in get_connection
    conn = self._get_connection()
  File "/home/madhu/my-bench/apps/frappe/frappe/database/mariadb/database.py", line 113, in _get_connection
    return self.create_connection()
  File "/home/madhu/my-bench/apps/frappe/frappe/database/mariadb/database.py", line 116, in create_connection
    return pymysql.connect(**self.get_connection_settings())
  File "/home/madhu/my-bench/env/lib/python3.10/site-packages/pymysql/connections.py", line 361, in __init__
    self.connect()
  File "/home/madhu/my-bench/env/lib/python3.10/site-packages/pymysql/connections.py", line 669, in connect
    self._request_authentication()
  File "/home/madhu/my-bench/env/lib/python3.10/site-packages/pymysql/connections.py", line 957, in _request_authentication
    auth_packet = self._read_packet()
  File "/home/madhu/my-bench/env/lib/python3.10/site-packages/pymysql/connections.py", line 775, in _read_packet
    packet.raise_for_error()
  File "/home/madhu/my-bench/env/lib/python3.10/site-packages/pymysql/protocol.py", line 219, in raise_for_error
    err.raise_mysql_exception(self._data)
  File "/home/madhu/my-bench/env/lib/python3.10/site-packages/pymysql/err.py", line 150, in raise_mysql_exception
    raise errorclass(errno, errval)
pymysql.err.OperationalError: (1045, "Access denied for user '_933473f0cb047aa4'@'localhost' (using password: YES)")
2024-11-06 15:58:46,673 ERROR scheduler Exception in Enqueue Events for Site newsite1
Traceback (most recent call last):
  File "/home/madhu/my-bench/apps/frappe/frappe/utils/scheduler.py", line 75, in enqueue_events_for_site
    if is_scheduler_inactive():
  File "/home/madhu/my-bench/apps/frappe/frappe/utils/scheduler.py", line 117, in is_scheduler_inactive
    if is_scheduler_disabled(verbose=verbose):
  File "/home/madhu/my-bench/apps/frappe/frappe/utils/scheduler.py", line 130, in is_scheduler_disabled
    frappe.db.get_single_value("System Settings", "enable_scheduler")
  File "/home/madhu/my-bench/apps/frappe/frappe/database/database.py", line 841, in get_single_value
    ).run()
  File "/home/madhu/my-bench/apps/frappe/frappe/query_builder/utils.py", line 87, in execute_query
    result = frappe.db.sql(query, params, *args, **kwargs)  # nosemgrep
  File "/home/madhu/my-bench/apps/frappe/frappe/database/database.py", line 211, in sql
    self.connect()
  File "/home/madhu/my-bench/apps/frappe/frappe/database/database.py", line 117, in connect
    self._conn: "MariadbConnection" | "PostgresConnection" = self.get_connection()
  File "/home/madhu/my-bench/apps/frappe/frappe/database/mariadb/database.py", line 107, in get_connection
    conn = self._get_connection()
  File "/home/madhu/my-bench/apps/frappe/frappe/database/mariadb/database.py", line 113, in _get_connection
    return self.create_connection()
  File "/home/madhu/my-bench/apps/frappe/frappe/database/mariadb/database.py", line 116, in create_connection
    return pymysql.connect(**self.get_connection_settings())
  File "/home/madhu/my-bench/env/lib/python3.10/site-packages/pymysql/connections.py", line 361, in __init__
    self.connect()
  File "/home/madhu/my-bench/env/lib/python3.10/site-packages/pymysql/connections.py", line 669, in connect
    self._request_authentication()
  File "/home/madhu/my-bench/env/lib/python3.10/site-packages/pymysql/connections.py", line 957, in _request_authentication
    auth_packet = self._read_packet()
  File "/home/madhu/my-bench/env/lib/python3.10/site-packages/pymysql/connections.py", line 775, in _read_packet
    packet.raise_for_error()
  File "/home/madhu/my-bench/env/lib/python3.10/site-packages/pymysql/protocol.py", line 219, in raise_for_error
    err.raise_mysql_exception(self._data)
  File "/home/madhu/my-bench/env/lib/python3.10/site-packages/pymysql/err.py", line 150, in raise_mysql_exception
    raise errorclass(errno, errval)
pymysql.err.OperationalError: (1045, "Access denied for user '_933473f0cb047aa4'@'localhost' (using password: YES)")
2024-11-06 15:59:47,114 ERROR scheduler Exception in Enqueue Events for Site newsite1
Traceback (most recent call last):
  File "/home/madhu/my-bench/apps/frappe/frappe/utils/scheduler.py", line 75, in enqueue_events_for_site
    if is_scheduler_inactive():
  File "/home/madhu/my-bench/apps/frappe/frappe/utils/scheduler.py", line 117, in is_scheduler_inactive
    if is_scheduler_disabled(verbose=verbose):
  File "/home/madhu/my-bench/apps/frappe/frappe/utils/scheduler.py", line 130, in is_scheduler_disabled
    frappe.db.get_single_value("System Settings", "enable_scheduler")
  File "/home/madhu/my-bench/apps/frappe/frappe/database/database.py", line 841, in get_single_value
    ).run()
  File "/home/madhu/my-bench/apps/frappe/frappe/query_builder/utils.py", line 87, in execute_query
    result = frappe.db.sql(query, params, *args, **kwargs)  # nosemgrep
  File "/home/madhu/my-bench/apps/frappe/frappe/database/database.py", line 211, in sql
    self.connect()
  File "/home/madhu/my-bench/apps/frappe/frappe/database/database.py", line 117, in connect
    self._conn: "MariadbConnection" | "PostgresConnection" = self.get_connection()
  File "/home/madhu/my-bench/apps/frappe/frappe/database/mariadb/database.py", line 107, in get_connection
    conn = self._get_connection()
  File "/home/madhu/my-bench/apps/frappe/frappe/database/mariadb/database.py", line 113, in _get_connection
    return self.create_connection()
  File "/home/madhu/my-bench/apps/frappe/frappe/database/mariadb/database.py", line 116, in create_connection
    return pymysql.connect(**self.get_connection_settings())
  File "/home/madhu/my-bench/env/lib/python3.10/site-packages/pymysql/connections.py", line 361, in __init__
    self.connect()
  File "/home/madhu/my-bench/env/lib/python3.10/site-packages/pymysql/connections.py", line 669, in connect
    self._request_authentication()
  File "/home/madhu/my-bench/env/lib/python3.10/site-packages/pymysql/connections.py", line 957, in _request_authentication
    auth_packet = self._read_packet()
  File "/home/madhu/my-bench/env/lib/python3.10/site-packages/pymysql/connections.py", line 775, in _read_packet
    packet.raise_for_error()
  File "/home/madhu/my-bench/env/lib/python3.10/site-packages/pymysql/protocol.py", line 219, in raise_for_error
    err.raise_mysql_exception(self._data)
  File "/home/madhu/my-bench/env/lib/python3.10/site-packages/pymysql/err.py", line 150, in raise_mysql_exception
    raise errorclass(errno, errval)
pymysql.err.OperationalError: (1045, "Access denied for user '_933473f0cb047aa4'@'localhost' (using password: YES)")
2024-11-06 16:00:47,352 ERROR scheduler Exception in Enqueue Events for Site newsite1
Traceback (most recent call last):
  File "/home/madhu/my-bench/apps/frappe/frappe/utils/scheduler.py", line 75, in enqueue_events_for_site
    if is_scheduler_inactive():
  File "/home/madhu/my-bench/apps/frappe/frappe/utils/scheduler.py", line 117, in is_scheduler_inactive
    if is_scheduler_disabled(verbose=verbose):
  File "/home/madhu/my-bench/apps/frappe/frappe/utils/scheduler.py", line 130, in is_scheduler_disabled
    frappe.db.get_single_value("System Settings", "enable_scheduler")
  File "/home/madhu/my-bench/apps/frappe/frappe/database/database.py", line 841, in get_single_value
    ).run()
  File "/home/madhu/my-bench/apps/frappe/frappe/query_builder/utils.py", line 87, in execute_query
    result = frappe.db.sql(query, params, *args, **kwargs)  # nosemgrep
  File "/home/madhu/my-bench/apps/frappe/frappe/database/database.py", line 211, in sql
    self.connect()
  File "/home/madhu/my-bench/apps/frappe/frappe/database/database.py", line 117, in connect
    self._conn: "MariadbConnection" | "PostgresConnection" = self.get_connection()
  File "/home/madhu/my-bench/apps/frappe/frappe/database/mariadb/database.py", line 107, in get_connection
    conn = self._get_connection()
  File "/home/madhu/my-bench/apps/frappe/frappe/database/mariadb/database.py", line 113, in _get_connection
    return self.create_connection()
  File "/home/madhu/my-bench/apps/frappe/frappe/database/mariadb/database.py", line 116, in create_connection
    return pymysql.connect(**self.get_connection_settings())
  File "/home/madhu/my-bench/env/lib/python3.10/site-packages/pymysql/connections.py", line 361, in __init__
    self.connect()
  File "/home/madhu/my-bench/env/lib/python3.10/site-packages/pymysql/connections.py", line 669, in connect
    self._request_authentication()
  File "/home/madhu/my-bench/env/lib/python3.10/site-packages/pymysql/connections.py", line 957, in _request_authentication
    auth_packet = self._read_packet()
  File "/home/madhu/my-bench/env/lib/python3.10/site-packages/pymysql/connections.py", line 775, in _read_packet
    packet.raise_for_error()
  File "/home/madhu/my-bench/env/lib/python3.10/site-packages/pymysql/protocol.py", line 219, in raise_for_error
    err.raise_mysql_exception(self._data)
  File "/home/madhu/my-bench/env/lib/python3.10/site-packages/pymysql/err.py", line 150, in raise_mysql_exception
    raise errorclass(errno, errval)
pymysql.err.OperationalError: (1045, "Access denied for user '_933473f0cb047aa4'@'localhost' (using password: YES)")
2024-11-06 16:01:47,748 ERROR scheduler Exception in Enqueue Events for Site newsite1
Traceback (most recent call last):
  File "/home/madhu/my-bench/apps/frappe/frappe/utils/scheduler.py", line 75, in enqueue_events_for_site
    if is_scheduler_inactive():
  File "/home/madhu/my-bench/apps/frappe/frappe/utils/scheduler.py", line 117, in is_scheduler_inactive
    if is_scheduler_disabled(verbose=verbose):
  File "/home/madhu/my-bench/apps/frappe/frappe/utils/scheduler.py", line 130, in is_scheduler_disabled
    frappe.db.get_single_value("System Settings", "enable_scheduler")
  File "/home/madhu/my-bench/apps/frappe/frappe/database/database.py", line 841, in get_single_value
    ).run()
  File "/home/madhu/my-bench/apps/frappe/frappe/query_builder/utils.py", line 87, in execute_query
    result = frappe.db.sql(query, params, *args, **kwargs)  # nosemgrep
  File "/home/madhu/my-bench/apps/frappe/frappe/database/database.py", line 211, in sql
    self.connect()
  File "/home/madhu/my-bench/apps/frappe/frappe/database/database.py", line 117, in connect
    self._conn: "MariadbConnection" | "PostgresConnection" = self.get_connection()
  File "/home/madhu/my-bench/apps/frappe/frappe/database/mariadb/database.py", line 107, in get_connection
    conn = self._get_connection()
  File "/home/madhu/my-bench/apps/frappe/frappe/database/mariadb/database.py", line 113, in _get_connection
    return self.create_connection()
  File "/home/madhu/my-bench/apps/frappe/frappe/database/mariadb/database.py", line 116, in create_connection
    return pymysql.connect(**self.get_connection_settings())
  File "/home/madhu/my-bench/env/lib/python3.10/site-packages/pymysql/connections.py", line 361, in __init__
    self.connect()
  File "/home/madhu/my-bench/env/lib/python3.10/site-packages/pymysql/connections.py", line 669, in connect
    self._request_authentication()
  File "/home/madhu/my-bench/env/lib/python3.10/site-packages/pymysql/connections.py", line 957, in _request_authentication
    auth_packet = self._read_packet()
  File "/home/madhu/my-bench/env/lib/python3.10/site-packages/pymysql/connections.py", line 775, in _read_packet
    packet.raise_for_error()
  File "/home/madhu/my-bench/env/lib/python3.10/site-packages/pymysql/protocol.py", line 219, in raise_for_error
    err.raise_mysql_exception(self._data)
  File "/home/madhu/my-bench/env/lib/python3.10/site-packages/pymysql/err.py", line 150, in raise_mysql_exception
    raise errorclass(errno, errval)
pymysql.err.OperationalError: (1045, "Access denied for user '_933473f0cb047aa4'@'localhost' (using password: YES)")
2024-11-06 16:02:48,099 ERROR scheduler Exception in Enqueue Events for Site newsite1
Traceback (most recent call last):
  File "/home/madhu/my-bench/apps/frappe/frappe/utils/scheduler.py", line 75, in enqueue_events_for_site
    if is_scheduler_inactive():
  File "/home/madhu/my-bench/apps/frappe/frappe/utils/scheduler.py", line 117, in is_scheduler_inactive
    if is_scheduler_disabled(verbose=verbose):
  File "/home/madhu/my-bench/apps/frappe/frappe/utils/scheduler.py", line 130, in is_scheduler_disabled
    frappe.db.get_single_value("System Settings", "enable_scheduler")
  File "/home/madhu/my-bench/apps/frappe/frappe/database/database.py", line 841, in get_single_value
    ).run()
  File "/home/madhu/my-bench/apps/frappe/frappe/query_builder/utils.py", line 87, in execute_query
    result = frappe.db.sql(query, params, *args, **kwargs)  # nosemgrep
  File "/home/madhu/my-bench/apps/frappe/frappe/database/database.py", line 211, in sql
    self.connect()
  File "/home/madhu/my-bench/apps/frappe/frappe/database/database.py", line 117, in connect
    self._conn: "MariadbConnection" | "PostgresConnection" = self.get_connection()
  File "/home/madhu/my-bench/apps/frappe/frappe/database/mariadb/database.py", line 107, in get_connection
    conn = self._get_connection()
  File "/home/madhu/my-bench/apps/frappe/frappe/database/mariadb/database.py", line 113, in _get_connection
    return self.create_connection()
  File "/home/madhu/my-bench/apps/frappe/frappe/database/mariadb/database.py", line 116, in create_connection
    return pymysql.connect(**self.get_connection_settings())
  File "/home/madhu/my-bench/env/lib/python3.10/site-packages/pymysql/connections.py", line 361, in __init__
    self.connect()
  File "/home/madhu/my-bench/env/lib/python3.10/site-packages/pymysql/connections.py", line 669, in connect
    self._request_authentication()
  File "/home/madhu/my-bench/env/lib/python3.10/site-packages/pymysql/connections.py", line 957, in _request_authentication
    auth_packet = self._read_packet()
  File "/home/madhu/my-bench/env/lib/python3.10/site-packages/pymysql/connections.py", line 775, in _read_packet
    packet.raise_for_error()
  File "/home/madhu/my-bench/env/lib/python3.10/site-packages/pymysql/protocol.py", line 219, in raise_for_error
    err.raise_mysql_exception(self._data)
  File "/home/madhu/my-bench/env/lib/python3.10/site-packages/pymysql/err.py", line 150, in raise_mysql_exception
    raise errorclass(errno, errval)
pymysql.err.OperationalError: (1045, "Access denied for user '_933473f0cb047aa4'@'localhost' (using password: YES)")
2024-11-06 16:03:48,704 ERROR scheduler Exception in Enqueue Events for Site newsite1
Traceback (most recent call last):
  File "/home/madhu/my-bench/apps/frappe/frappe/utils/scheduler.py", line 75, in enqueue_events_for_site
    if is_scheduler_inactive():
  File "/home/madhu/my-bench/apps/frappe/frappe/utils/scheduler.py", line 117, in is_scheduler_inactive
    if is_scheduler_disabled(verbose=verbose):
  File "/home/madhu/my-bench/apps/frappe/frappe/utils/scheduler.py", line 130, in is_scheduler_disabled
    frappe.db.get_single_value("System Settings", "enable_scheduler")
  File "/home/madhu/my-bench/apps/frappe/frappe/database/database.py", line 841, in get_single_value
    ).run()
  File "/home/madhu/my-bench/apps/frappe/frappe/query_builder/utils.py", line 87, in execute_query
    result = frappe.db.sql(query, params, *args, **kwargs)  # nosemgrep
  File "/home/madhu/my-bench/apps/frappe/frappe/database/database.py", line 211, in sql
    self.connect()
  File "/home/madhu/my-bench/apps/frappe/frappe/database/database.py", line 117, in connect
    self._conn: "MariadbConnection" | "PostgresConnection" = self.get_connection()
  File "/home/madhu/my-bench/apps/frappe/frappe/database/mariadb/database.py", line 107, in get_connection
    conn = self._get_connection()
  File "/home/madhu/my-bench/apps/frappe/frappe/database/mariadb/database.py", line 113, in _get_connection
    return self.create_connection()
  File "/home/madhu/my-bench/apps/frappe/frappe/database/mariadb/database.py", line 116, in create_connection
    return pymysql.connect(**self.get_connection_settings())
  File "/home/madhu/my-bench/env/lib/python3.10/site-packages/pymysql/connections.py", line 361, in __init__
    self.connect()
  File "/home/madhu/my-bench/env/lib/python3.10/site-packages/pymysql/connections.py", line 669, in connect
    self._request_authentication()
  File "/home/madhu/my-bench/env/lib/python3.10/site-packages/pymysql/connections.py", line 957, in _request_authentication
    auth_packet = self._read_packet()
  File "/home/madhu/my-bench/env/lib/python3.10/site-packages/pymysql/connections.py", line 775, in _read_packet
    packet.raise_for_error()
  File "/home/madhu/my-bench/env/lib/python3.10/site-packages/pymysql/protocol.py", line 219, in raise_for_error
    err.raise_mysql_exception(self._data)
  File "/home/madhu/my-bench/env/lib/python3.10/site-packages/pymysql/err.py", line 150, in raise_mysql_exception
    raise errorclass(errno, errval)
pymysql.err.OperationalError: (1045, "Access denied for user '_933473f0cb047aa4'@'localhost' (using password: YES)")
2024-11-06 16:04:49,127 ERROR scheduler Exception in Enqueue Events for Site newsite1
Traceback (most recent call last):
  File "/home/madhu/my-bench/apps/frappe/frappe/utils/scheduler.py", line 75, in enqueue_events_for_site
    if is_scheduler_inactive():
  File "/home/madhu/my-bench/apps/frappe/frappe/utils/scheduler.py", line 117, in is_scheduler_inactive
    if is_scheduler_disabled(verbose=verbose):
  File "/home/madhu/my-bench/apps/frappe/frappe/utils/scheduler.py", line 130, in is_scheduler_disabled
    frappe.db.get_single_value("System Settings", "enable_scheduler")
  File "/home/madhu/my-bench/apps/frappe/frappe/database/database.py", line 841, in get_single_value
    ).run()
  File "/home/madhu/my-bench/apps/frappe/frappe/query_builder/utils.py", line 87, in execute_query
    result = frappe.db.sql(query, params, *args, **kwargs)  # nosemgrep
  File "/home/madhu/my-bench/apps/frappe/frappe/database/database.py", line 211, in sql
    self.connect()
  File "/home/madhu/my-bench/apps/frappe/frappe/database/database.py", line 117, in connect
    self._conn: "MariadbConnection" | "PostgresConnection" = self.get_connection()
  File "/home/madhu/my-bench/apps/frappe/frappe/database/mariadb/database.py", line 107, in get_connection
    conn = self._get_connection()
  File "/home/madhu/my-bench/apps/frappe/frappe/database/mariadb/database.py", line 113, in _get_connection
    return self.create_connection()
  File "/home/madhu/my-bench/apps/frappe/frappe/database/mariadb/database.py", line 116, in create_connection
    return pymysql.connect(**self.get_connection_settings())
  File "/home/madhu/my-bench/env/lib/python3.10/site-packages/pymysql/connections.py", line 361, in __init__
    self.connect()
  File "/home/madhu/my-bench/env/lib/python3.10/site-packages/pymysql/connections.py", line 669, in connect
    self._request_authentication()
  File "/home/madhu/my-bench/env/lib/python3.10/site-packages/pymysql/connections.py", line 957, in _request_authentication
    auth_packet = self._read_packet()
  File "/home/madhu/my-bench/env/lib/python3.10/site-packages/pymysql/connections.py", line 775, in _read_packet
    packet.raise_for_error()
  File "/home/madhu/my-bench/env/lib/python3.10/site-packages/pymysql/protocol.py", line 219, in raise_for_error
    err.raise_mysql_exception(self._data)
  File "/home/madhu/my-bench/env/lib/python3.10/site-packages/pymysql/err.py", line 150, in raise_mysql_exception
    raise errorclass(errno, errval)
pymysql.err.OperationalError: (1045, "Access denied for user '_933473f0cb047aa4'@'localhost' (using password: YES)")
2024-11-06 16:05:49,384 ERROR scheduler Exception in Enqueue Events for Site newsite1
Traceback (most recent call last):
  File "/home/madhu/my-bench/apps/frappe/frappe/utils/scheduler.py", line 75, in enqueue_events_for_site
    if is_scheduler_inactive():
  File "/home/madhu/my-bench/apps/frappe/frappe/utils/scheduler.py", line 117, in is_scheduler_inactive
    if is_scheduler_disabled(verbose=verbose):
  File "/home/madhu/my-bench/apps/frappe/frappe/utils/scheduler.py", line 130, in is_scheduler_disabled
    frappe.db.get_single_value("System Settings", "enable_scheduler")
  File "/home/madhu/my-bench/apps/frappe/frappe/database/database.py", line 841, in get_single_value
    ).run()
  File "/home/madhu/my-bench/apps/frappe/frappe/query_builder/utils.py", line 87, in execute_query
    result = frappe.db.sql(query, params, *args, **kwargs)  # nosemgrep
  File "/home/madhu/my-bench/apps/frappe/frappe/database/database.py", line 211, in sql
    self.connect()
  File "/home/madhu/my-bench/apps/frappe/frappe/database/database.py", line 117, in connect
    self._conn: "MariadbConnection" | "PostgresConnection" = self.get_connection()
  File "/home/madhu/my-bench/apps/frappe/frappe/database/mariadb/database.py", line 107, in get_connection
    conn = self._get_connection()
  File "/home/madhu/my-bench/apps/frappe/frappe/database/mariadb/database.py", line 113, in _get_connection
    return self.create_connection()
  File "/home/madhu/my-bench/apps/frappe/frappe/database/mariadb/database.py", line 116, in create_connection
    return pymysql.connect(**self.get_connection_settings())
  File "/home/madhu/my-bench/env/lib/python3.10/site-packages/pymysql/connections.py", line 361, in __init__
    self.connect()
  File "/home/madhu/my-bench/env/lib/python3.10/site-packages/pymysql/connections.py", line 669, in connect
    self._request_authentication()
  File "/home/madhu/my-bench/env/lib/python3.10/site-packages/pymysql/connections.py", line 957, in _request_authentication
    auth_packet = self._read_packet()
  File "/home/madhu/my-bench/env/lib/python3.10/site-packages/pymysql/connections.py", line 775, in _read_packet
    packet.raise_for_error()
  File "/home/madhu/my-bench/env/lib/python3.10/site-packages/pymysql/protocol.py", line 219, in raise_for_error
    err.raise_mysql_exception(self._data)
  File "/home/madhu/my-bench/env/lib/python3.10/site-packages/pymysql/err.py", line 150, in raise_mysql_exception
    raise errorclass(errno, errval)
pymysql.err.OperationalError: (1045, "Access denied for user '_933473f0cb047aa4'@'localhost' (using password: YES)")
2024-11-06 16:06:49,791 ERROR scheduler Exception in Enqueue Events for Site newsite1
Traceback (most recent call last):
  File "/home/madhu/my-bench/apps/frappe/frappe/utils/scheduler.py", line 75, in enqueue_events_for_site
    if is_scheduler_inactive():
  File "/home/madhu/my-bench/apps/frappe/frappe/utils/scheduler.py", line 117, in is_scheduler_inactive
    if is_scheduler_disabled(verbose=verbose):
  File "/home/madhu/my-bench/apps/frappe/frappe/utils/scheduler.py", line 130, in is_scheduler_disabled
    frappe.db.get_single_value("System Settings", "enable_scheduler")
  File "/home/madhu/my-bench/apps/frappe/frappe/database/database.py", line 841, in get_single_value
    ).run()
  File "/home/madhu/my-bench/apps/frappe/frappe/query_builder/utils.py", line 87, in execute_query
    result = frappe.db.sql(query, params, *args, **kwargs)  # nosemgrep
  File "/home/madhu/my-bench/apps/frappe/frappe/database/database.py", line 211, in sql
    self.connect()
  File "/home/madhu/my-bench/apps/frappe/frappe/database/database.py", line 117, in connect
    self._conn: "MariadbConnection" | "PostgresConnection" = self.get_connection()
  File "/home/madhu/my-bench/apps/frappe/frappe/database/mariadb/database.py", line 107, in get_connection
    conn = self._get_connection()
  File "/home/madhu/my-bench/apps/frappe/frappe/database/mariadb/database.py", line 113, in _get_connection
    return self.create_connection()
  File "/home/madhu/my-bench/apps/frappe/frappe/database/mariadb/database.py", line 116, in create_connection
    return pymysql.connect(**self.get_connection_settings())
  File "/home/madhu/my-bench/env/lib/python3.10/site-packages/pymysql/connections.py", line 361, in __init__
    self.connect()
  File "/home/madhu/my-bench/env/lib/python3.10/site-packages/pymysql/connections.py", line 669, in connect
    self._request_authentication()
  File "/home/madhu/my-bench/env/lib/python3.10/site-packages/pymysql/connections.py", line 957, in _request_authentication
    auth_packet = self._read_packet()
  File "/home/madhu/my-bench/env/lib/python3.10/site-packages/pymysql/connections.py", line 775, in _read_packet
    packet.raise_for_error()
  File "/home/madhu/my-bench/env/lib/python3.10/site-packages/pymysql/protocol.py", line 219, in raise_for_error
    err.raise_mysql_exception(self._data)
  File "/home/madhu/my-bench/env/lib/python3.10/site-packages/pymysql/err.py", line 150, in raise_mysql_exception
    raise errorclass(errno, errval)
pymysql.err.OperationalError: (1045, "Access denied for user '_933473f0cb047aa4'@'localhost' (using password: YES)")
2024-11-06 16:07:50,163 ERROR scheduler Exception in Enqueue Events for Site newsite1
Traceback (most recent call last):
  File "/home/madhu/my-bench/apps/frappe/frappe/utils/scheduler.py", line 75, in enqueue_events_for_site
    if is_scheduler_inactive():
  File "/home/madhu/my-bench/apps/frappe/frappe/utils/scheduler.py", line 117, in is_scheduler_inactive
    if is_scheduler_disabled(verbose=verbose):
  File "/home/madhu/my-bench/apps/frappe/frappe/utils/scheduler.py", line 130, in is_scheduler_disabled
    frappe.db.get_single_value("System Settings", "enable_scheduler")
  File "/home/madhu/my-bench/apps/frappe/frappe/database/database.py", line 841, in get_single_value
    ).run()
  File "/home/madhu/my-bench/apps/frappe/frappe/query_builder/utils.py", line 87, in execute_query
    result = frappe.db.sql(query, params, *args, **kwargs)  # nosemgrep
  File "/home/madhu/my-bench/apps/frappe/frappe/database/database.py", line 211, in sql
    self.connect()
  File "/home/madhu/my-bench/apps/frappe/frappe/database/database.py", line 117, in connect
    self._conn: "MariadbConnection" | "PostgresConnection" = self.get_connection()
  File "/home/madhu/my-bench/apps/frappe/frappe/database/mariadb/database.py", line 107, in get_connection
    conn = self._get_connection()
  File "/home/madhu/my-bench/apps/frappe/frappe/database/mariadb/database.py", line 113, in _get_connection
    return self.create_connection()
  File "/home/madhu/my-bench/apps/frappe/frappe/database/mariadb/database.py", line 116, in create_connection
    return pymysql.connect(**self.get_connection_settings())
  File "/home/madhu/my-bench/env/lib/python3.10/site-packages/pymysql/connections.py", line 361, in __init__
    self.connect()
  File "/home/madhu/my-bench/env/lib/python3.10/site-packages/pymysql/connections.py", line 669, in connect
    self._request_authentication()
  File "/home/madhu/my-bench/env/lib/python3.10/site-packages/pymysql/connections.py", line 957, in _request_authentication
    auth_packet = self._read_packet()
  File "/home/madhu/my-bench/env/lib/python3.10/site-packages/pymysql/connections.py", line 775, in _read_packet
    packet.raise_for_error()
  File "/home/madhu/my-bench/env/lib/python3.10/site-packages/pymysql/protocol.py", line 219, in raise_for_error
    err.raise_mysql_exception(self._data)
  File "/home/madhu/my-bench/env/lib/python3.10/site-packages/pymysql/err.py", line 150, in raise_mysql_exception
    raise errorclass(errno, errval)
pymysql.err.OperationalError: (1045, "Access denied for user '_933473f0cb047aa4'@'localhost' (using password: YES)")
2024-11-06 16:08:50,435 ERROR scheduler Exception in Enqueue Events for Site newsite1
Traceback (most recent call last):
  File "/home/madhu/my-bench/apps/frappe/frappe/utils/scheduler.py", line 75, in enqueue_events_for_site
    if is_scheduler_inactive():
  File "/home/madhu/my-bench/apps/frappe/frappe/utils/scheduler.py", line 117, in is_scheduler_inactive
    if is_scheduler_disabled(verbose=verbose):
  File "/home/madhu/my-bench/apps/frappe/frappe/utils/scheduler.py", line 130, in is_scheduler_disabled
    frappe.db.get_single_value("System Settings", "enable_scheduler")
  File "/home/madhu/my-bench/apps/frappe/frappe/database/database.py", line 841, in get_single_value
    ).run()
  File "/home/madhu/my-bench/apps/frappe/frappe/query_builder/utils.py", line 87, in execute_query
    result = frappe.db.sql(query, params, *args, **kwargs)  # nosemgrep
  File "/home/madhu/my-bench/apps/frappe/frappe/database/database.py", line 211, in sql
    self.connect()
  File "/home/madhu/my-bench/apps/frappe/frappe/database/database.py", line 117, in connect
    self._conn: "MariadbConnection" | "PostgresConnection" = self.get_connection()
  File "/home/madhu/my-bench/apps/frappe/frappe/database/mariadb/database.py", line 107, in get_connection
    conn = self._get_connection()
  File "/home/madhu/my-bench/apps/frappe/frappe/database/mariadb/database.py", line 113, in _get_connection
    return self.create_connection()
  File "/home/madhu/my-bench/apps/frappe/frappe/database/mariadb/database.py", line 116, in create_connection
    return pymysql.connect(**self.get_connection_settings())
  File "/home/madhu/my-bench/env/lib/python3.10/site-packages/pymysql/connections.py", line 361, in __init__
    self.connect()
  File "/home/madhu/my-bench/env/lib/python3.10/site-packages/pymysql/connections.py", line 669, in connect
    self._request_authentication()
  File "/home/madhu/my-bench/env/lib/python3.10/site-packages/pymysql/connections.py", line 957, in _request_authentication
    auth_packet = self._read_packet()
  File "/home/madhu/my-bench/env/lib/python3.10/site-packages/pymysql/connections.py", line 775, in _read_packet
    packet.raise_for_error()
  File "/home/madhu/my-bench/env/lib/python3.10/site-packages/pymysql/protocol.py", line 219, in raise_for_error
    err.raise_mysql_exception(self._data)
  File "/home/madhu/my-bench/env/lib/python3.10/site-packages/pymysql/err.py", line 150, in raise_mysql_exception
    raise errorclass(errno, errval)
pymysql.err.OperationalError: (1045, "Access denied for user '_933473f0cb047aa4'@'localhost' (using password: YES)")
2024-11-06 16:09:50,938 ERROR scheduler Exception in Enqueue Events for Site newsite1
Traceback (most recent call last):
  File "/home/madhu/my-bench/apps/frappe/frappe/utils/scheduler.py", line 75, in enqueue_events_for_site
    if is_scheduler_inactive():
  File "/home/madhu/my-bench/apps/frappe/frappe/utils/scheduler.py", line 117, in is_scheduler_inactive
    if is_scheduler_disabled(verbose=verbose):
  File "/home/madhu/my-bench/apps/frappe/frappe/utils/scheduler.py", line 130, in is_scheduler_disabled
    frappe.db.get_single_value("System Settings", "enable_scheduler")
  File "/home/madhu/my-bench/apps/frappe/frappe/database/database.py", line 841, in get_single_value
    ).run()
  File "/home/madhu/my-bench/apps/frappe/frappe/query_builder/utils.py", line 87, in execute_query
    result = frappe.db.sql(query, params, *args, **kwargs)  # nosemgrep
  File "/home/madhu/my-bench/apps/frappe/frappe/database/database.py", line 211, in sql
    self.connect()
  File "/home/madhu/my-bench/apps/frappe/frappe/database/database.py", line 117, in connect
    self._conn: "MariadbConnection" | "PostgresConnection" = self.get_connection()
  File "/home/madhu/my-bench/apps/frappe/frappe/database/mariadb/database.py", line 107, in get_connection
    conn = self._get_connection()
  File "/home/madhu/my-bench/apps/frappe/frappe/database/mariadb/database.py", line 113, in _get_connection
    return self.create_connection()
  File "/home/madhu/my-bench/apps/frappe/frappe/database/mariadb/database.py", line 116, in create_connection
    return pymysql.connect(**self.get_connection_settings())
  File "/home/madhu/my-bench/env/lib/python3.10/site-packages/pymysql/connections.py", line 361, in __init__
    self.connect()
  File "/home/madhu/my-bench/env/lib/python3.10/site-packages/pymysql/connections.py", line 669, in connect
    self._request_authentication()
  File "/home/madhu/my-bench/env/lib/python3.10/site-packages/pymysql/connections.py", line 957, in _request_authentication
    auth_packet = self._read_packet()
  File "/home/madhu/my-bench/env/lib/python3.10/site-packages/pymysql/connections.py", line 775, in _read_packet
    packet.raise_for_error()
  File "/home/madhu/my-bench/env/lib/python3.10/site-packages/pymysql/protocol.py", line 219, in raise_for_error
    err.raise_mysql_exception(self._data)
  File "/home/madhu/my-bench/env/lib/python3.10/site-packages/pymysql/err.py", line 150, in raise_mysql_exception
    raise errorclass(errno, errval)
pymysql.err.OperationalError: (1045, "Access denied for user '_933473f0cb047aa4'@'localhost' (using password: YES)")
2024-11-06 16:10:51,579 ERROR scheduler Exception in Enqueue Events for Site newsite1
Traceback (most recent call last):
  File "/home/madhu/my-bench/apps/frappe/frappe/utils/scheduler.py", line 75, in enqueue_events_for_site
    if is_scheduler_inactive():
  File "/home/madhu/my-bench/apps/frappe/frappe/utils/scheduler.py", line 117, in is_scheduler_inactive
    if is_scheduler_disabled(verbose=verbose):
  File "/home/madhu/my-bench/apps/frappe/frappe/utils/scheduler.py", line 130, in is_scheduler_disabled
    frappe.db.get_single_value("System Settings", "enable_scheduler")
  File "/home/madhu/my-bench/apps/frappe/frappe/database/database.py", line 841, in get_single_value
    ).run()
  File "/home/madhu/my-bench/apps/frappe/frappe/query_builder/utils.py", line 87, in execute_query
    result = frappe.db.sql(query, params, *args, **kwargs)  # nosemgrep
  File "/home/madhu/my-bench/apps/frappe/frappe/database/database.py", line 211, in sql
    self.connect()
  File "/home/madhu/my-bench/apps/frappe/frappe/database/database.py", line 117, in connect
    self._conn: "MariadbConnection" | "PostgresConnection" = self.get_connection()
  File "/home/madhu/my-bench/apps/frappe/frappe/database/mariadb/database.py", line 107, in get_connection
    conn = self._get_connection()
  File "/home/madhu/my-bench/apps/frappe/frappe/database/mariadb/database.py", line 113, in _get_connection
    return self.create_connection()
  File "/home/madhu/my-bench/apps/frappe/frappe/database/mariadb/database.py", line 116, in create_connection
    return pymysql.connect(**self.get_connection_settings())
  File "/home/madhu/my-bench/env/lib/python3.10/site-packages/pymysql/connections.py", line 361, in __init__
    self.connect()
  File "/home/madhu/my-bench/env/lib/python3.10/site-packages/pymysql/connections.py", line 669, in connect
    self._request_authentication()
  File "/home/madhu/my-bench/env/lib/python3.10/site-packages/pymysql/connections.py", line 957, in _request_authentication
    auth_packet = self._read_packet()
  File "/home/madhu/my-bench/env/lib/python3.10/site-packages/pymysql/connections.py", line 775, in _read_packet
    packet.raise_for_error()
  File "/home/madhu/my-bench/env/lib/python3.10/site-packages/pymysql/protocol.py", line 219, in raise_for_error
    err.raise_mysql_exception(self._data)
  File "/home/madhu/my-bench/env/lib/python3.10/site-packages/pymysql/err.py", line 150, in raise_mysql_exception
    raise errorclass(errno, errval)
pymysql.err.OperationalError: (1045, "Access denied for user '_933473f0cb047aa4'@'localhost' (using password: YES)")
2024-11-06 16:11:51,873 ERROR scheduler Exception in Enqueue Events for Site newsite1
Traceback (most recent call last):
  File "/home/madhu/my-bench/apps/frappe/frappe/utils/scheduler.py", line 75, in enqueue_events_for_site
    if is_scheduler_inactive():
  File "/home/madhu/my-bench/apps/frappe/frappe/utils/scheduler.py", line 117, in is_scheduler_inactive
    if is_scheduler_disabled(verbose=verbose):
  File "/home/madhu/my-bench/apps/frappe/frappe/utils/scheduler.py", line 130, in is_scheduler_disabled
    frappe.db.get_single_value("System Settings", "enable_scheduler")
  File "/home/madhu/my-bench/apps/frappe/frappe/database/database.py", line 841, in get_single_value
    ).run()
  File "/home/madhu/my-bench/apps/frappe/frappe/query_builder/utils.py", line 87, in execute_query
    result = frappe.db.sql(query, params, *args, **kwargs)  # nosemgrep
  File "/home/madhu/my-bench/apps/frappe/frappe/database/database.py", line 211, in sql
    self.connect()
  File "/home/madhu/my-bench/apps/frappe/frappe/database/database.py", line 117, in connect
    self._conn: "MariadbConnection" | "PostgresConnection" = self.get_connection()
  File "/home/madhu/my-bench/apps/frappe/frappe/database/mariadb/database.py", line 107, in get_connection
    conn = self._get_connection()
  File "/home/madhu/my-bench/apps/frappe/frappe/database/mariadb/database.py", line 113, in _get_connection
    return self.create_connection()
  File "/home/madhu/my-bench/apps/frappe/frappe/database/mariadb/database.py", line 116, in create_connection
    return pymysql.connect(**self.get_connection_settings())
  File "/home/madhu/my-bench/env/lib/python3.10/site-packages/pymysql/connections.py", line 361, in __init__
    self.connect()
  File "/home/madhu/my-bench/env/lib/python3.10/site-packages/pymysql/connections.py", line 669, in connect
    self._request_authentication()
  File "/home/madhu/my-bench/env/lib/python3.10/site-packages/pymysql/connections.py", line 957, in _request_authentication
    auth_packet = self._read_packet()
  File "/home/madhu/my-bench/env/lib/python3.10/site-packages/pymysql/connections.py", line 775, in _read_packet
    packet.raise_for_error()
  File "/home/madhu/my-bench/env/lib/python3.10/site-packages/pymysql/protocol.py", line 219, in raise_for_error
    err.raise_mysql_exception(self._data)
  File "/home/madhu/my-bench/env/lib/python3.10/site-packages/pymysql/err.py", line 150, in raise_mysql_exception
    raise errorclass(errno, errval)
pymysql.err.OperationalError: (1045, "Access denied for user '_933473f0cb047aa4'@'localhost' (using password: YES)")
2024-11-06 16:12:52,373 ERROR scheduler Exception in Enqueue Events for Site newsite1
Traceback (most recent call last):
  File "/home/madhu/my-bench/apps/frappe/frappe/utils/scheduler.py", line 75, in enqueue_events_for_site
    if is_scheduler_inactive():
  File "/home/madhu/my-bench/apps/frappe/frappe/utils/scheduler.py", line 117, in is_scheduler_inactive
    if is_scheduler_disabled(verbose=verbose):
  File "/home/madhu/my-bench/apps/frappe/frappe/utils/scheduler.py", line 130, in is_scheduler_disabled
    frappe.db.get_single_value("System Settings", "enable_scheduler")
  File "/home/madhu/my-bench/apps/frappe/frappe/database/database.py", line 841, in get_single_value
    ).run()
  File "/home/madhu/my-bench/apps/frappe/frappe/query_builder/utils.py", line 87, in execute_query
    result = frappe.db.sql(query, params, *args, **kwargs)  # nosemgrep
  File "/home/madhu/my-bench/apps/frappe/frappe/database/database.py", line 211, in sql
    self.connect()
  File "/home/madhu/my-bench/apps/frappe/frappe/database/database.py", line 117, in connect
    self._conn: "MariadbConnection" | "PostgresConnection" = self.get_connection()
  File "/home/madhu/my-bench/apps/frappe/frappe/database/mariadb/database.py", line 107, in get_connection
    conn = self._get_connection()
  File "/home/madhu/my-bench/apps/frappe/frappe/database/mariadb/database.py", line 113, in _get_connection
    return self.create_connection()
  File "/home/madhu/my-bench/apps/frappe/frappe/database/mariadb/database.py", line 116, in create_connection
    return pymysql.connect(**self.get_connection_settings())
  File "/home/madhu/my-bench/env/lib/python3.10/site-packages/pymysql/connections.py", line 361, in __init__
    self.connect()
  File "/home/madhu/my-bench/env/lib/python3.10/site-packages/pymysql/connections.py", line 669, in connect
    self._request_authentication()
  File "/home/madhu/my-bench/env/lib/python3.10/site-packages/pymysql/connections.py", line 957, in _request_authentication
    auth_packet = self._read_packet()
  File "/home/madhu/my-bench/env/lib/python3.10/site-packages/pymysql/connections.py", line 775, in _read_packet
    packet.raise_for_error()
  File "/home/madhu/my-bench/env/lib/python3.10/site-packages/pymysql/protocol.py", line 219, in raise_for_error
    err.raise_mysql_exception(self._data)
  File "/home/madhu/my-bench/env/lib/python3.10/site-packages/pymysql/err.py", line 150, in raise_mysql_exception
    raise errorclass(errno, errval)
pymysql.err.OperationalError: (1045, "Access denied for user '_933473f0cb047aa4'@'localhost' (using password: YES)")
2024-11-06 16:13:54,093 ERROR scheduler Exception in Enqueue Events for Site newsite1
Traceback (most recent call last):
  File "/home/madhu/my-bench/apps/frappe/frappe/utils/scheduler.py", line 75, in enqueue_events_for_site
    if is_scheduler_inactive():
  File "/home/madhu/my-bench/apps/frappe/frappe/utils/scheduler.py", line 117, in is_scheduler_inactive
    if is_scheduler_disabled(verbose=verbose):
  File "/home/madhu/my-bench/apps/frappe/frappe/utils/scheduler.py", line 130, in is_scheduler_disabled
    frappe.db.get_single_value("System Settings", "enable_scheduler")
  File "/home/madhu/my-bench/apps/frappe/frappe/database/database.py", line 841, in get_single_value
    ).run()
  File "/home/madhu/my-bench/apps/frappe/frappe/query_builder/utils.py", line 87, in execute_query
    result = frappe.db.sql(query, params, *args, **kwargs)  # nosemgrep
  File "/home/madhu/my-bench/apps/frappe/frappe/database/database.py", line 211, in sql
    self.connect()
  File "/home/madhu/my-bench/apps/frappe/frappe/database/database.py", line 117, in connect
    self._conn: "MariadbConnection" | "PostgresConnection" = self.get_connection()
  File "/home/madhu/my-bench/apps/frappe/frappe/database/mariadb/database.py", line 107, in get_connection
    conn = self._get_connection()
  File "/home/madhu/my-bench/apps/frappe/frappe/database/mariadb/database.py", line 113, in _get_connection
    return self.create_connection()
  File "/home/madhu/my-bench/apps/frappe/frappe/database/mariadb/database.py", line 116, in create_connection
    return pymysql.connect(**self.get_connection_settings())
  File "/home/madhu/my-bench/env/lib/python3.10/site-packages/pymysql/connections.py", line 361, in __init__
    self.connect()
  File "/home/madhu/my-bench/env/lib/python3.10/site-packages/pymysql/connections.py", line 669, in connect
    self._request_authentication()
  File "/home/madhu/my-bench/env/lib/python3.10/site-packages/pymysql/connections.py", line 957, in _request_authentication
    auth_packet = self._read_packet()
  File "/home/madhu/my-bench/env/lib/python3.10/site-packages/pymysql/connections.py", line 775, in _read_packet
    packet.raise_for_error()
  File "/home/madhu/my-bench/env/lib/python3.10/site-packages/pymysql/protocol.py", line 219, in raise_for_error
    err.raise_mysql_exception(self._data)
  File "/home/madhu/my-bench/env/lib/python3.10/site-packages/pymysql/err.py", line 150, in raise_mysql_exception
    raise errorclass(errno, errval)
pymysql.err.OperationalError: (1045, "Access denied for user '_933473f0cb047aa4'@'localhost' (using password: YES)")
2024-11-06 16:15:15,308 ERROR scheduler Exception in Enqueue Events for Site newsite1
Traceback (most recent call last):
  File "/home/madhu/my-bench/apps/frappe/frappe/utils/scheduler.py", line 75, in enqueue_events_for_site
    if is_scheduler_inactive():
  File "/home/madhu/my-bench/apps/frappe/frappe/utils/scheduler.py", line 117, in is_scheduler_inactive
    if is_scheduler_disabled(verbose=verbose):
  File "/home/madhu/my-bench/apps/frappe/frappe/utils/scheduler.py", line 130, in is_scheduler_disabled
    frappe.db.get_single_value("System Settings", "enable_scheduler")
  File "/home/madhu/my-bench/apps/frappe/frappe/database/database.py", line 841, in get_single_value
    ).run()
  File "/home/madhu/my-bench/apps/frappe/frappe/query_builder/utils.py", line 87, in execute_query
    result = frappe.db.sql(query, params, *args, **kwargs)  # nosemgrep
  File "/home/madhu/my-bench/apps/frappe/frappe/database/database.py", line 211, in sql
    self.connect()
  File "/home/madhu/my-bench/apps/frappe/frappe/database/database.py", line 117, in connect
    self._conn: "MariadbConnection" | "PostgresConnection" = self.get_connection()
  File "/home/madhu/my-bench/apps/frappe/frappe/database/mariadb/database.py", line 107, in get_connection
    conn = self._get_connection()
  File "/home/madhu/my-bench/apps/frappe/frappe/database/mariadb/database.py", line 113, in _get_connection
    return self.create_connection()
  File "/home/madhu/my-bench/apps/frappe/frappe/database/mariadb/database.py", line 116, in create_connection
    return pymysql.connect(**self.get_connection_settings())
  File "/home/madhu/my-bench/env/lib/python3.10/site-packages/pymysql/connections.py", line 361, in __init__
    self.connect()
  File "/home/madhu/my-bench/env/lib/python3.10/site-packages/pymysql/connections.py", line 669, in connect
    self._request_authentication()
  File "/home/madhu/my-bench/env/lib/python3.10/site-packages/pymysql/connections.py", line 957, in _request_authentication
    auth_packet = self._read_packet()
  File "/home/madhu/my-bench/env/lib/python3.10/site-packages/pymysql/connections.py", line 775, in _read_packet
    packet.raise_for_error()
  File "/home/madhu/my-bench/env/lib/python3.10/site-packages/pymysql/protocol.py", line 219, in raise_for_error
    err.raise_mysql_exception(self._data)
  File "/home/madhu/my-bench/env/lib/python3.10/site-packages/pymysql/err.py", line 150, in raise_mysql_exception
    raise errorclass(errno, errval)
pymysql.err.OperationalError: (1045, "Access denied for user '_933473f0cb047aa4'@'localhost' (using password: YES)")
2024-11-06 16:16:15,708 ERROR scheduler Exception in Enqueue Events for Site newsite1
Traceback (most recent call last):
  File "/home/madhu/my-bench/apps/frappe/frappe/utils/scheduler.py", line 75, in enqueue_events_for_site
    if is_scheduler_inactive():
  File "/home/madhu/my-bench/apps/frappe/frappe/utils/scheduler.py", line 117, in is_scheduler_inactive
    if is_scheduler_disabled(verbose=verbose):
  File "/home/madhu/my-bench/apps/frappe/frappe/utils/scheduler.py", line 130, in is_scheduler_disabled
    frappe.db.get_single_value("System Settings", "enable_scheduler")
  File "/home/madhu/my-bench/apps/frappe/frappe/database/database.py", line 841, in get_single_value
    ).run()
  File "/home/madhu/my-bench/apps/frappe/frappe/query_builder/utils.py", line 87, in execute_query
    result = frappe.db.sql(query, params, *args, **kwargs)  # nosemgrep
  File "/home/madhu/my-bench/apps/frappe/frappe/database/database.py", line 211, in sql
    self.connect()
  File "/home/madhu/my-bench/apps/frappe/frappe/database/database.py", line 117, in connect
    self._conn: "MariadbConnection" | "PostgresConnection" = self.get_connection()
  File "/home/madhu/my-bench/apps/frappe/frappe/database/mariadb/database.py", line 107, in get_connection
    conn = self._get_connection()
  File "/home/madhu/my-bench/apps/frappe/frappe/database/mariadb/database.py", line 113, in _get_connection
    return self.create_connection()
  File "/home/madhu/my-bench/apps/frappe/frappe/database/mariadb/database.py", line 116, in create_connection
    return pymysql.connect(**self.get_connection_settings())
  File "/home/madhu/my-bench/env/lib/python3.10/site-packages/pymysql/connections.py", line 361, in __init__
    self.connect()
  File "/home/madhu/my-bench/env/lib/python3.10/site-packages/pymysql/connections.py", line 669, in connect
    self._request_authentication()
  File "/home/madhu/my-bench/env/lib/python3.10/site-packages/pymysql/connections.py", line 957, in _request_authentication
    auth_packet = self._read_packet()
  File "/home/madhu/my-bench/env/lib/python3.10/site-packages/pymysql/connections.py", line 775, in _read_packet
    packet.raise_for_error()
  File "/home/madhu/my-bench/env/lib/python3.10/site-packages/pymysql/protocol.py", line 219, in raise_for_error
    err.raise_mysql_exception(self._data)
  File "/home/madhu/my-bench/env/lib/python3.10/site-packages/pymysql/err.py", line 150, in raise_mysql_exception
    raise errorclass(errno, errval)
pymysql.err.OperationalError: (1045, "Access denied for user '_933473f0cb047aa4'@'localhost' (using password: YES)")
2024-11-06 16:17:16,217 ERROR scheduler Exception in Enqueue Events for Site newsite1
Traceback (most recent call last):
  File "/home/madhu/my-bench/apps/frappe/frappe/utils/scheduler.py", line 75, in enqueue_events_for_site
    if is_scheduler_inactive():
  File "/home/madhu/my-bench/apps/frappe/frappe/utils/scheduler.py", line 117, in is_scheduler_inactive
    if is_scheduler_disabled(verbose=verbose):
  File "/home/madhu/my-bench/apps/frappe/frappe/utils/scheduler.py", line 130, in is_scheduler_disabled
    frappe.db.get_single_value("System Settings", "enable_scheduler")
  File "/home/madhu/my-bench/apps/frappe/frappe/database/database.py", line 841, in get_single_value
    ).run()
  File "/home/madhu/my-bench/apps/frappe/frappe/query_builder/utils.py", line 87, in execute_query
    result = frappe.db.sql(query, params, *args, **kwargs)  # nosemgrep
  File "/home/madhu/my-bench/apps/frappe/frappe/database/database.py", line 211, in sql
    self.connect()
  File "/home/madhu/my-bench/apps/frappe/frappe/database/database.py", line 117, in connect
    self._conn: "MariadbConnection" | "PostgresConnection" = self.get_connection()
  File "/home/madhu/my-bench/apps/frappe/frappe/database/mariadb/database.py", line 107, in get_connection
    conn = self._get_connection()
  File "/home/madhu/my-bench/apps/frappe/frappe/database/mariadb/database.py", line 113, in _get_connection
    return self.create_connection()
  File "/home/madhu/my-bench/apps/frappe/frappe/database/mariadb/database.py", line 116, in create_connection
    return pymysql.connect(**self.get_connection_settings())
  File "/home/madhu/my-bench/env/lib/python3.10/site-packages/pymysql/connections.py", line 361, in __init__
    self.connect()
  File "/home/madhu/my-bench/env/lib/python3.10/site-packages/pymysql/connections.py", line 669, in connect
    self._request_authentication()
  File "/home/madhu/my-bench/env/lib/python3.10/site-packages/pymysql/connections.py", line 957, in _request_authentication
    auth_packet = self._read_packet()
  File "/home/madhu/my-bench/env/lib/python3.10/site-packages/pymysql/connections.py", line 775, in _read_packet
    packet.raise_for_error()
  File "/home/madhu/my-bench/env/lib/python3.10/site-packages/pymysql/protocol.py", line 219, in raise_for_error
    err.raise_mysql_exception(self._data)
  File "/home/madhu/my-bench/env/lib/python3.10/site-packages/pymysql/err.py", line 150, in raise_mysql_exception
    raise errorclass(errno, errval)
pymysql.err.OperationalError: (1045, "Access denied for user '_933473f0cb047aa4'@'localhost' (using password: YES)")
2024-11-06 16:18:16,816 ERROR scheduler Exception in Enqueue Events for Site newsite1
Traceback (most recent call last):
  File "/home/madhu/my-bench/apps/frappe/frappe/utils/scheduler.py", line 75, in enqueue_events_for_site
    if is_scheduler_inactive():
  File "/home/madhu/my-bench/apps/frappe/frappe/utils/scheduler.py", line 117, in is_scheduler_inactive
    if is_scheduler_disabled(verbose=verbose):
  File "/home/madhu/my-bench/apps/frappe/frappe/utils/scheduler.py", line 130, in is_scheduler_disabled
    frappe.db.get_single_value("System Settings", "enable_scheduler")
  File "/home/madhu/my-bench/apps/frappe/frappe/database/database.py", line 841, in get_single_value
    ).run()
  File "/home/madhu/my-bench/apps/frappe/frappe/query_builder/utils.py", line 87, in execute_query
    result = frappe.db.sql(query, params, *args, **kwargs)  # nosemgrep
  File "/home/madhu/my-bench/apps/frappe/frappe/database/database.py", line 211, in sql
    self.connect()
  File "/home/madhu/my-bench/apps/frappe/frappe/database/database.py", line 117, in connect
    self._conn: "MariadbConnection" | "PostgresConnection" = self.get_connection()
  File "/home/madhu/my-bench/apps/frappe/frappe/database/mariadb/database.py", line 107, in get_connection
    conn = self._get_connection()
  File "/home/madhu/my-bench/apps/frappe/frappe/database/mariadb/database.py", line 113, in _get_connection
    return self.create_connection()
  File "/home/madhu/my-bench/apps/frappe/frappe/database/mariadb/database.py", line 116, in create_connection
    return pymysql.connect(**self.get_connection_settings())
  File "/home/madhu/my-bench/env/lib/python3.10/site-packages/pymysql/connections.py", line 361, in __init__
    self.connect()
  File "/home/madhu/my-bench/env/lib/python3.10/site-packages/pymysql/connections.py", line 669, in connect
    self._request_authentication()
  File "/home/madhu/my-bench/env/lib/python3.10/site-packages/pymysql/connections.py", line 957, in _request_authentication
    auth_packet = self._read_packet()
  File "/home/madhu/my-bench/env/lib/python3.10/site-packages/pymysql/connections.py", line 775, in _read_packet
    packet.raise_for_error()
  File "/home/madhu/my-bench/env/lib/python3.10/site-packages/pymysql/protocol.py", line 219, in raise_for_error
    err.raise_mysql_exception(self._data)
  File "/home/madhu/my-bench/env/lib/python3.10/site-packages/pymysql/err.py", line 150, in raise_mysql_exception
    raise errorclass(errno, errval)
pymysql.err.OperationalError: (1045, "Access denied for user '_933473f0cb047aa4'@'localhost' (using password: YES)")
